Workbook
Name tbl_huur_onz_pt: Tabellen!$A$2:$A$252
Name tbl_huur_onz_bd: Tabellen!$B$2:$B$252
Name tbl_energielabel_lbl: Tabellen!$D$2:$D$12
Name tbl_energielabel_fac: Tabellen!$E$2:$E$12
Name tbl_bouwjaar_grens: Tabellen!$D$15:$D$21
Name tbl_bouwjaar_fac: Tabellen!$E$15:$E$21
Name tbl_corop_regio: Tabellen!$G$2:$G$41
Name tbl_corop_woz: Tabellen!$H$2:$H$41
Name tbl_keuken_grens: Tabellen!$J$2:$J$5
Name tbl_keuken_basis: Tabellen!$K$2:$K$5
Name tbl_keuken_extra_naam: Tabellen!$J$8:$J$21
Name tbl_keuken_extra_pt: Tabellen!$K$8:$K$21
Name tbl_san_basis_naam: Tabellen!$J$24:$J$32
Name tbl_san_basis_pt: Tabellen!$K$24:$K$32
Name tbl_san_extra_naam: Tabellen!$J$35:$J$42
Name tbl_san_extra_pt: Tabellen!$K$35:$K$42
Name tbl_parkeer_type: Tabellen!$M$2:$M$4
Name tbl_parkeer_pt: Tabellen!$N$2:$N$4

Sheet Invoer
A1: WWSO PUNTENTELLING — INVOER PANDGEGEVENS (per 1 januari 2026)
A2: Pandgegevens
A4: Adres
A5: Stad | C5: Stad
A6: WOZ-waarde (€)
A7: WOZ-peildatum
A8: WOZ-oppervlak (m²)
A9: COROP-gebied
A10: Energielabel
A11: Energielabel ingangsdatum
A12: Bouwjaar
A13: Soort woning
A14: Aantal kamers (1-12)
A15: Aantal woningen in complex
A16: Monument
A17: Nr | B17: Naam ruimte | C17: Type | D17: Opp. m² | E17: Verdieping | F17: Verwarmd | G17: Verkoeld | H17: K1 | I17: K2 | J17: K3 | K17: K4 | L17: K5 | M17: K6 | N17: K7 | O17: K8 | P17: K9 | Q17: K10 | R17: K11 | S17: K12 | T17: n_kamers
A18: =ROW()-17 | T18: =COUNTIF(H18:S18,"J")
A19: =ROW()-17 | T19: =COUNTIF(H19:S19,"J")
A20: =ROW()-17 | T20: =COUNTIF(H20:S20,"J")
A21: =ROW()-17 | T21: =COUNTIF(H21:S21,"J")
A22: =ROW()-17 | T22: =COUNTIF(H22:S22,"J")
A23: =ROW()-17 | T23: =COUNTIF(H23:S23,"J")
A24: =ROW()-17 | T24: =COUNTIF(H24:S24,"J")
A25: =ROW()-17 | T25: =COUNTIF(H25:S25,"J")
A26: =ROW()-17 | T26: =COUNTIF(H26:S26,"J")
A27: =ROW()-17 | T27: =COUNTIF(H27:S27,"J")
A28: =ROW()-17 | T28: =COUNTIF(H28:S28,"J")
A29: =ROW()-17 | T29: =COUNTIF(H29:S29,"J")
... A57: =ROW()-17 | T57: =COUNTIF(H57:S57,"J")

Sheet Voorzieningen
A1: WWSO — VOORZIENINGEN (per 1 januari 2026)
A3: Keuken 1
A4: Ruimte-nr (1-40)
A5: Aanrechtlengte (m)
A6: Afzuiginstallatie
A7: Kookplaat inductie
A8: Kookplaat keramisch
A9: Kookplaat gas
A10: Koelkast
A11: Vrieskast
A12: Oven elektrisch
A13: Oven gas
... A19: Kokend-waterfunctie
A20: Basispunten aanrecht | B20: =IFERROR(INDEX(tbl_keuken_basis,MATCH(B5,tbl_keuken_grens,1)),0)
A21: Extra punten (raw) | B21: =IF(B6="J",0.75,0)+IF(B7="J",1.75,0)+IF(B8="J",1.0,0)+IF(B9="J",0.5,0)+IF(B10="J",1.0,0)+IF(B11="J",0.75,0)+IF(B12="J",1.0,0)+IF(B13="J",0.5,0)+IF(B14="J",1.0,0)+IF(B15="J",1.5,0)+IF(B16="J",0.75,0)+IF(B17="J",0.25,0)+IF(B18="J",0.5,0)+IF(B19="J",0.5,0)
A22: Extra gecapped | B22: =MIN(B21,B20)
A23: Totaal keuken punten | B23: =B20+B22
A24: n_kamers met toegang | B24: =IFERROR(INDEX(Invoer!$T$18:$T$57,B4),0)
A25: Per kamer | B25: =IFERROR(B23/IF(B24=0,1,B24),0)
A26: Keuken 2
A27: Ruimte-nr (1-40)
A28: Aanrechtlengte (m)
A29: Afzuiginstallatie
A30: Kookplaat inductie
A31: Kookplaat keramisch
A32: Kookplaat gas
A33: Koelkast
A34: Vrieskast
A35: Oven elektrisch
A36: Oven gas
A37: Magnetron
... A42: Kokend-waterfunctie
A43: Basispunten aanrecht | B43: =IFERROR(INDEX(tbl_keuken_basis,MATCH(B28,tbl_keuken_grens,1)),0)
A44: Extra punten (raw) | B44: =IF(B29="J",0.75,0)+IF(B30="J",1.75,0)+IF(B31="J",1.0,0)+IF(B32="J",0.5,0)+IF(B33="J",1.0,0)+IF(B34="J",0.75,0)+IF(B35="J",1.0,0)+IF(B36="J",0.5,0)+IF(B37="J",1.0,0)+IF(B38="J",1.5,0)+IF(B39="J",0.75,0)+IF(B40="J",0.25,0)+IF(B41="J",0.5,0)+IF(B42="J",0.5,0)
A45: Extra gecapped | B45: =MIN(B44,B43)
A46: Totaal keuken punten | B46: =B43+B45
A47: n_kamers met toegang | B47: =IFERROR(INDEX(Invoer!$T$18:$T$57,B27),0)
A48: Per kamer | B48: =IFERROR(B46/IF(B47=0,1,B47),0)
A49: Keuken 3
A50: Ruimte-nr (1-40)
...

Sheet Tabellen
A1: Punten | B1: Max huurprijs (€) | D1: Energielabel | E1: Factor (pt/m²) | G1: COROP-gebied | H1: WOZ gem/m² (1-1-2026) | J1: Aanrecht max (m) | K1: Basispunten | M1: Parkeertype | N1: Punten | P1: COROP (lijst)
A2: 0 | B2: 0 | D2: A++++ | E2: 1 | G2: Oost-Groningen | H2: 2184 | J2: 2 | K2: 4 | M2: Garage (afgesloten) | N2: 9 | P2: Oost-Groningen
A3: 1 | B3: 10.33 | D3: A+++ | E3: 0.95 | G3: Delfzijl en omgeving | H3: 2015 | J3: 3 | K3: 7 | M3: Overkapping/carport | N3: 6 | P3: Delfzijl en omgeving
A4: 2 | B4: 20.56 | D4: A++ | E4: 0.85 | G4: Overig Groningen | H4: 2777 | J4: 5 | K4: 10 | M4: Open parkeerplaats | N4: 4 | P4: Overig Groningen
A5: 3 | B5: 30.77 | D5: A+ | E5: 0.75 | G5: Friesland (Noord) | H5: 2275 | J5: 99 | K5: 13 | M5: Bron: Beleidsboek WWSO onzelfstandig, januari 2026 | P5: Friesland (Noord)
A6: 4 | B6: 40.89 | D6: A | E6: 0.65 | G6: Friesland (Zuid-West) | H6: 2393 | J6: Bron: Beleidsboek WWSO onzelfstandig, januari 2026 | P6: Friesland (Zuid-West)
A7: 5 | B7: 51.12 | D7: B | E7: 0.5 | G7: Friesland (Zuid-Oost) | H7: 2583 | J7: Voorziening | K7: Punten | P7: Friesland (Zuid-Oost)
A8: 6 | B8: 61.29 | D8: C | E8: 0.35 | G8: Drenthe (Noord) | H8: 2738 | J8: Afzuiginstallatie | K8: 0.75 | P8: Drenthe (Noord)
A9: 7 | B9: 71.47 | D9: D | E9: 0.2 | G9: Drenthe (Zuid-Oost) | H9: 2269 | J9: Kookplaat inductie | K9: 1.75 | P9: Drenthe (Zuid-Oost)
A10: 8 | B10: 81.62 | D10: E | E10: -0.05 | G10: Drenthe (Zuid-West) | H10: 2640 | J10: Kookplaat keramisch | K10: 1 | P10: Drenthe (Zuid-West)
A11: 9 | B11: 91.85 | D11: F | E11: -0.1 | G11: Overijssel (Noord) | H11: 3065 | J11: Kookplaat gas | K11: 0.5 | P11: Overijssel (Noord)
A12: 10 | B12: 102.06 | D12: G | E12: -0.15 | G12: Overijssel (Zuid-West) | H12: 3326 | J12: Koelkast | K12: 1 | P12: Overijssel (Zuid-West)
A13: 11 | B13: 112.23 | D13: Bron: Beleidsboek WWSO onzelfstandig, januari 2026 | G13: Twente | H13: 2958 | J13: Vrieskast | K13: 0.75 | P13: Twente
A14: 12 | B14: 122.38 | D14: Bouwjaar t/m | E14: Punten/m² | G14: Veluwe | H14: 3815 | J14: Oven elektrisch | K14: 1 | P14: Veluwe
A15: 13 | B15: 132.57 | D15: 2099 | E15: 0.65 | G15: Achterhoek | H15: 2820 | J15: Oven gas | K15: 0.5 | P15: Achterhoek
A16: 14 | B16: 142.76 | D16: 2001 | E16: 0.5 | G16: Arnhem/Nijmegen | H16: 3511 | J16: Magnetron | K16: 1 | P16: Arnhem/Nijmegen
A17: 15 | B17: 152.92 | D17: 1999 | E17: 0.35 | G17: Gelderland (Zuid-West) | H17: 3403 | J17: Vaatwasmachine | K17: 1.5 | P17: Gelderland (Zuid-West)
A18: 16 | B18: 163.13 | D18: 1991 | E18: 0.2 | G18: Utrecht | H18: 4684 | J18: Extra kastruimte (60cm) | K18: 0.75 | P18: Utrecht
A19: 17 | B19: 173.33 | D19: 1983 | E19: -0.05 | G19: Kop van Noord-Holland | H19: 3124 | J19: Éénhandsmengkraan | K19: 0.25 | P19: Kop van Noord-Holland
A20: 18 | B20: 183.54 | D20: 1978 | E20: -0.1 | G20: Alkmaar en omgeving | H20: 4164 | J20: Thermostatische mengkraan | K20: 0.5 | P20: Alkmaar en omgeving
A21: 19 | B21: 193.63 | D21: 1976 | E21: -0.15 | G21: IJmond | H21: 4206 | J21: Kokend-waterfunctie | K21: 0.5 | P21: IJmond
A22: 20 | B22: 203.87 | D22: Bron: Beleidsboek WWSO onzelfstandig, januari 2026 | G22: Agglomeratie Haarlem | H22: 5582 | J22: Bron: Beleidsboek WWSO onzelfstandig, januari 2026 | P22: Agglomeratie Haarlem
A23: 21 | B23: 214.04 | G23: Zaanstreek | H23: 4099 | J23: Sanitair | K23: Punten | P23: Zaanstreek
A24: 22 | B24: 224.29 | G24: Groot Amsterdam | H24: 6378 | J24: Staand toilet toiletruimte | K24: 3 | P24: Groot Amsterdam
A25: 23 | B25: 234.44 | G25: Het Gooi- en Vechtstreek | H25: 5100 | J25: Staand toilet badkamer | K25: 2 | P25: Het Gooi- en Vechtstreek
A26: 24 | B26: 244.59 | G26: Agglomeratie Leiden en Bollenstreek | H26: 4668 | J26: Hangend toilet toiletruimte | K26: 3.75 | P26: Agglomeratie Leiden en Bollenstreek
A27: 25 | B27: 254.83 | G27: Agglomeratie 's-Gravenhage | H27: 4342 | J27: Hangend toilet badkamer | K27: 2.75 | P27: Agglomeratie 's-Gravenhage
A28: 26 | B28: 264.95 | G28: Delft en Westland | H28: 4386 | J28: Wastafel | K28: 1 | P28: Delft en Westland
A29: 27 | B29: 275.1 | G29: Zuid-Holland (Oost) | H29: 3875 | J29: Meerpersoonswastafel | K29: 1.5 | P29: Zuid-Holland (Oost)
A30: 28 | B30: 285.37 | G30: Groot-Rijnmond | H30: 3884 | J30: Douche | K30: 3 | P30: Groot-Rijnmond
A31: 29 | B31: 295.54 | G31: Zuid-Holland (Zuidoost-Zuid) | H31: 3582 | J31: Bad | K31: 5 | P31: Zuid-Holland (Zuidoost-Zuid)
A32: 30 | B32: 305.73 | G32: Zeeuwsch-Vlaanderen | H32: 2287 | J32: Bad+douche combinatie | K32: 6 | P32: Zeeuwsch-Vlaanderen
A33: 31 | B33: 315.89 | G33: Overig Zeeland | H33: 2806 | J33: Bron: Beleidsboek WWSO onzelfstandig, januari 2026 | P33: Overig Zeeland
A34: 32 | B34: 326.12 | G34: Brabant (West-Noord) | H34: 3323 | J34: Sanitair extra | K34: Punten | P34: Brabant (West-Noord)
A35: 33 | B35: 336.29 | G35: Brabant (Midden-Noord) | H35: 3370 | J35: Bubbelfunctie bad | K35: 1.5 | P35: Brabant (Midden-Noord)
A36: 34 | B36: 346.45 | G36: Brabant (Noordoost-Noord) | H36: 3456 | J36: Doucheafscheiding volledig | K36: 1.25 | P36: Brabant (Noordoost-Noord)
A37: 35 | B37: 356.69 | G37: Brabant (Zuidoost-Noord) | H37: 3531 | J37: Handdoekenradiator | K37: 0.75 | P37: Brabant (Zuidoost-Noord)
A38: 36 | B38: 366.9 | G38: Limburg (Noord) | H38: 2693 | J38: Ingebouwd kastje+wastafel | K38: 1 | P38: Limburg (Noord)
A39: 37 | B39: 377.02 | G39: Limburg (Midden) | H39: 2633 | J39: Kastruimte (min 40cm) | K39: 0.75 | P39: Limburg (Midden)
A40: 38 | B40: 387.18 | G40: Limburg (Zuid) | H40: 2486 | J40: Stopcontact (per stuk) | K40: 0.25 | P40: Limburg (Zuid)
...

Sheet Berekening
A1: PUNTENTELLING — BEREKENING (§ 2 beleidsboek WWSO jan 2026)
A2: Rubriek | B2: Omschrijving | C2: K1 | D2: K2 | E2: K3 | F2: K4 | G2: K5 | H2: K6 | I2: K7 | J2: K8 | K2: K9 | L2: K10 | M2: K11 | N2: K12 | O2: Pandtotaal
A3: R1 | B3: Oppervlakte vertrekken (§2.2.1) | C3: =ROUND(SUMPRODUCT((Invoer!$C$18:$C$57="Privévertrek")*(Invoer!$H$18:$H$57="J")*Invoer!$D$18:$D$57)+SUMPRODUCT(((Invoer!$C$18:$C$57="Keuken")+(Invoer!$C$18:$C$57="Badruimte"))*(Invoer!$H$18:$H$57="J")*Invoer!$D$18:$D$57/IF(Invoer!$T$18:$T$57=0,1,Invoer!$T$18:$T$57)),0) | D3: =ROUND(SUMPRODUCT((Invoer!$C$18:$C$57="Privévertrek")*(Invoer!$I$18:$I$57="J")*Invoer!$D$18:$D$57)+SUMPRODUCT(((Invoer!$C$18:$C$57="Keuken")+(Invoer!$C$18:$C$57="Badruimte"))*(Invoer!$I$18:$I$57="J")*Invoer!$D$18:$D$57/IF(Invoer!$T$18:$T$57=0,1,Invoer!$T$18:$T$57)),0) | E3: =ROUND(SUMPRODUCT((Invoer!$C$18:$C$57="Privévertrek")*(Invoer!$J$18:$J$57="J")*Invoer!$D$18:$D$57)+SUMPRODUCT(((Invoer!$C$18:$C$57="Keuken")+(Invoer!$C$18:$C$57="Badruimte"))*(Invoer!$J$18:$J$57="J")*Invoer!$D$18:$D$57/IF(Invoer!$T$18:$T$57=0,1,Invoer!$T$18:$T$57)),0) | F3: =ROUND(SUMPRODUCT((Invoer!$C$18:$C$57="Privévertrek")*(Invoer!$K$18:$K$57="J")*Invoer!$D$18:$D$57)+SUMPRODUCT(((Invoer!$C$18:$C$57="Keuken")+(Invoer!$C$18:$C$57="Badruimte"))*(Invoer!$K$18:$K$57="J")*Invoer!$D$18:$D$57/IF(Invoer!$T$18:$T$57=0,1,Invoer!$T$18:$T$57)),0) | G3: =ROUND(SUMPRODUCT((Invoer!$C$18:$C$57="Privévertrek")*(Invoer!$L$18:$L$57="J")*Invoer!$D$18:$D$57)+SUMPRODUCT(((Invoer!$C$18:$C$57="Keuken")+(Invoer!$C$18:$C$57="Badruimte"))*(Invoer!$L$18:$L$57="J")*Invoer!$D$18:$D$57/IF(Invoer!$T$18:$T$57=0,1,Invoer!$T$18:$T$57)),0) | H3: =ROUND(SUMPRODUCT((Invoer!$C$18:$C$57="Privévertrek")*(Invoer!$M$18:$M$57="J")*Invoer!$D$18:$D$57)+SUMPRODUCT(((Invoer!$C$18:$C$57="Keuken")+(Invoer!$C$18:$C$57="Badruimte"))*(Invoer!$M$18:$M$57="J")*Invoer!$D$18:$D$57/IF(Invoer!$T$18:$T$57=0,1,Invoer!$T$18:$T$57)),0) | I3: =ROUND(SUMPRODUCT((Invoer!$C$18:$C$57="Privévertrek")*(Invoer!$N$18:$N$57="J")*Invoer!$D$18:$D$57)+SUMPRODUCT(((Invoer!$C$18:$C$57="Keuken")+(Invoer!$C$18:$C$57="Badruimte"))*(Invoer!$N$18:$N$57="J")*Invoer!$D$18:$D$57/IF(Invoer!$T$18:$T$57=0,1,Invoer!$T$18:$T$57)),0) | J3: =ROUND(SUMPRODUCT((Invoer!$C$18:$C$57="Privévertrek")*(Invoer!$O$18:$O$57="J")*Invoer!$D$18:$D$57)+SUMPRODUCT(((Invoer!$C$18:$C$57="Keuken")+(Invoer!$C$18:$C$57="Badruimte"))*(Invoer!$O$18:$O$57="J")*Invoer!$D$18:$D$57/IF(Invoer!$T$18:$T$57=0,1,Invoer!$T$18:$T$57)),0) | K3: =ROUND(SUMPRODUCT((Invoer!$C$18:$C$57="Privévertrek")*(Invoer!$P$18:$P$57="J")*Invoer!$D$18:$D$57)+SUMPRODUCT(((Invoer!$C$18:$C$57="Keuken")+(Invoer!$C$18:$C$57="Badruimte"))*(Invoer!$P$18:$P$57="J")*Invoer!$D$18:$D$57/IF(Invoer!$T$18:$T$57=0,1,Invoer!$T$18:$T$57)),0) | L3: =ROUND(SUMPRODUCT((Invoer!$C$18:$C$57="Privévertrek")*(Invoer!$Q$18:$Q$57="J")*Invoer!$D$18:$D$57)+SUMPRODUCT(((Invoer!$C$18:$C$57="Keuken")+(Invoer!$C$18:$C$57="Badruimte"))*(Invoer!$Q$18:$Q$57="J")*Invoer!$D$18:$D$57/IF(Invoer!$T$18:$T$57=0,1,Invoer!$T$18:$T$57)),0) | M3: =ROUND(SUMPRODUCT((Invoer!$C$18:$C$57="Privévertrek")*(Invoer!$R$18:$R$57="J")*Invoer!$D$18:$D$57)+SUMPRODUCT(((Invoer!$C$18:$C$57="Keuken")+(Invoer!$C$18:$C$57="Badruimte"))*(Invoer!$R$18:$R$57="J")*Invoer!$D$18:$D$57/IF(Invoer!$T$18:$T$57=0,1,Invoer!$T$18:$T$57)),0) | N3: =ROUND(SUMPRODUCT((Invoer!$C$18:$C$57="Privévertrek")*(Invoer!$S$18:$S$57="J")*Invoer!$D$18:$D$57)+SUMPRODUCT(((Invoer!$C$18:$C$57="Keuken")+(Invoer!$C$18:$C$57="Badruimte"))*(Invoer!$S$18:$S$57="J")*Invoer!$D$18:$D$57/IF(Invoer!$T$18:$T$57=0,1,Invoer!$T$18:$T$57)),0) | O3: =SUM(C3:N3)
A4: R2 | B4: Oppervlakte overige ruimten (§2.2.2) | C4: =FLOOR(SUMPRODUCT(((Invoer!$C$18:$C$57="Berging")+(Invoer!$C$18:$C$57="Bijkeuken")+(Invoer!$C$18:$C$57="Wasruimte")+(Invoer!$C$18:$C$57="Overige ruimte")+(Invoer!$C$18:$C$57="Toiletruimte"))*(Invoer!$H$18:$H$57="J")*Invoer!$D$18:$D$57*0.75/IF(Invoer!$T$18:$T$57=0,1,Invoer!$T$18:$T$57))+0.125,0.25) | D4: =FLOOR(SUMPRODUCT(((Invoer!$C$18:$C$57="Berging")+(Invoer!$C$18:$C$57="Bijkeuken")+(Invoer!$C$18:$C$57="Wasruimte")+(Invoer!$C$18:$C$57="Overige ruimte")+(Invoer!$C$18:$C$57="Toiletruimte"))*(Invoer!$I$18:$I$57="J")*Invoer!$D$18:$D$57*0.75/IF(Invoer!$T$18:$T$57=0,1,Invoer!$T$18:$T$57))+0.125,0.25) | E4: =FLOOR(SUMPRODUCT(((Invoer!$C$18:$C$57="Berging")+(Invoer!$C$18:$C$57="Bijkeuken")+(Invoer!$C$18:$C$57="Wasruimte")+(Invoer!$C$18:$C$57="Overige ruimte")+(Invoer!$C$18:$C$57="Toiletruimte"))*(Invoer!$J$18:$J$57="J")*Invoer!$D$18:$D$57*0.75/IF(Invoer!$T$18:$T$57=0,1,Invoer!$T$18:$T$57))+0.125,0.25) | F4: =FLOOR(SUMPRODUCT(((Invoer!$C$18:$C$57="Berging")+(Invoer!$C$18:$C$57="Bijkeuken")+(Invoer!$C$18:$C$57="Wasruimte")+(Invoer!$C$18:$C$57="Overige ruimte")+(Invoer!$C$18:$C$57="Toiletruimte"))*(Invoer!$K$18:$K$57="J")*Invoer!$D$18:$D$57*0.75/IF(Invoer!$T$18:$T$57=0,1,Invoer!$T$18:$T$57))+0.125,0.25) | G4: =FLOOR(SUMPRODUCT(((Invoer!$C$18:$C$57="Berging")+(Invoer!$C$18:$C$57="Bijkeuken")+(Invoer!$C$18:$C$57="Wasruimte")+(Invoer!$C$18:$C$57="Overige ruimte")+(Invoer!$C$18:$C$57="Toiletruimte"))*(Invoer!$L$18:$L$57="J")*Invoer!$D$18:$D$57*0.75/IF(Invoer!$T$18:$T$57=0,1,Invoer!$T$18:$T$57))+0.125,0.25) | H4: =FLOOR(SUMPRODUCT(((Invoer!$C$18:$C$57="Berging")+(Invoer!$C$18:$C$57="Bijkeuken")+(Invoer!$C$18:$C$57="Wasruimte")+(Invoer!$C$18:$C$57="Overige ruimte")+(Invoer!$C$18:$C$57="Toiletruimte"))*(Invoer!$M$18:$M$57="J")*Invoer!$D$18:$D$57*0.75/IF(Invoer!$T$18:$T$57=0,1,Invoer!$T$18:$T$57))+0.125,0.25) | I4: =FLOOR(SUMPRODUCT(((Invoer!$C$18:$C$57="Berging")+(Invoer!$C$18:$C$57="Bijkeuken")+(Invoer!$C$18:$C$57="Wasruimte")+(Invoer!$C$18:$C$57="Overige ruimte")+(Invoer!$C$18:$C$57="Toiletruimte"))*(Invoer!$N$18:$N$57="J")*Invoer!$D$18:$D$57*0.75/IF(Invoer!$T$18:$T$57=0,1,Invoer!$T$18:$T$57))+0.125,0.25) | J4: =FLOOR(SUMPRODUCT(((Invoer!$C$18:$C$57="Berging")+(Invoer!$C$18:$C$57="Bijkeuken")+(Invoer!$C$18:$C$57="Wasruimte")+(Invoer!$C$18:$C$57="Overige ruimte")+(Invoer!$C$18:$C$57="Toiletruimte"))*(Invoer!$O$18:$O$57="J")*Invoer!$D$18:$D$57*0.75/IF(Invoer!$T$18:$T$57=0,1,Invoer!$T$18:$T$57))+0.125,0.25) | K4: =FLOOR(SUMPRODUCT(((Invoer!$C$18:$C$57="Berging")+(Invoer!$C$18:$C$57="Bijkeuken")+(Invoer!$C$18:$C$57="Wasruimte")+(Invoer!$C$18:$C$57="Overige ruimte")+(Invoer!$C$18:$C$57="Toiletruimte"))*(Invoer!$P$18:$P$57="J")*Invoer!$D$18:$D$57*0.75/IF(Invoer!$T$18:$T$57=0,1,Invoer!$T$18:$T$57))+0.125,0.25) | L4: =FLOOR(SUMPRODUCT(((Invoer!$C$18:$C$57="Berging")+(Invoer!$C$18:$C$57="Bijkeuken")+(Invoer!$C$18:$C$57="Wasruimte")+(Invoer!$C$18:$C$57="Overige ruimte")+(Invoer!$C$18:$C$57="Toiletruimte"))*(Invoer!$Q$18:$Q$57="J")*Invoer!$D$18:$D$57*0.75/IF(Invoer!$T$18:$T$57=0,1,Invoer!$T$18:$T$57))+0.125,0.25) | M4: =FLOOR(SUMPRODUCT(((Invoer!$C$18:$C$57="Berging")+(Invoer!$C$18:$C$57="Bijkeuken")+(Invoer!$C$18:$C$57="Wasruimte")+(Invoer!$C$18:$C$57="Overige ruimte")+(Invoer!$C$18:$C$57="Toiletruimte"))*(Invoer!$R$18:$R$57="J")*Invoer!$D$18:$D$57*0.75/IF(Invoer!$T$18:$T$57=0,1,Invoer!$T$18:$T$57))+0.125,0.25) | N4: =FLOOR(SUMPRODUCT(((Invoer!$C$18:$C$57="Berging")+(Invoer!$C$18:$C$57="Bijkeuken")+(Invoer!$C$18:$C$57="Wasruimte")+(Invoer!$C$18:$C$57="Overige ruimte")+(Invoer!$C$18:$C$57="Toiletruimte"))*(Invoer!$S$18:$S$57="J")*Invoer!$D$18:$D$57*0.75/IF(Invoer!$T$18:$T$57=0,1,Invoer!$T$18:$T$57))+0.125,0.25) | O4: =SUM(C4:N4)
A5: R3 | B5: Verwarming (§2.3) | C5: =FLOOR(SUMPRODUCT(((Invoer!$C$18:$C$57="Privévertrek")+(Invoer!$C$18:$C$57="Keuken")+(Invoer!$C$18:$C$57="Badruimte"))*(Invoer!$F$18:$F$57="J")*(Invoer!$H$18:$H$57="J")*2/IF(Invoer!$T$18:$T$57=0,1,Invoer!$T$18:$T$57))+MIN(4,SUMPRODUCT(((Invoer!$C$18:$C$57="Berging")+(Invoer!$C$18:$C$57="Bijkeuken")+(Invoer!$C$18:$C$57="Wasruimte")+(Invoer!$C$18:$C$57="Overige ruimte")+(Invoer!$C$18:$C$57="Verkeersruimte"))*(Invoer!$F$18:$F$57="J")*(Invoer!$H$18:$H$57="J")*1/IF(Invoer!$T$18:$T$57=0,1,Invoer!$T$18:$T$57)))+MIN(2,SUMPRODUCT(((Invoer!$C$18:$C$57="Privévertrek")+(Invoer!$C$18:$C$57="Keuken")+(Invoer!$C$18:$C$57="Badruimte"))*(Invoer!$F$18:$F$57="J")*(Invoer!$G$18:$G$57="J")*(Invoer!$H$18:$H$57="J")*1/IF(Invoer!$T$18:$T$57=0,1,Invoer!$T$18:$T$57)))+0.125,0.25) | D5: =FLOOR(SUMPRODUCT(((Invoer!$C$18:$C$57="Privévertrek")+(Invoer!$C$18:$C$57="Keuken")+(Invoer!$C$18:$C$57="Badruimte"))*(Invoer!$F$18:$F$57="J")*(Invoer!$I$18:$I$57="J")*2/IF(Invoer!$T$18:$T$57=0,1,Invoer!$T$18:$T$57))+MIN(4,SUMPRODUCT(((Invoer!$C$18:$C$57="Berging")+(Invoer!$C$18:$C$57="Bijkeuken")+(Invoer!$C$18:$C$57="Wasruimte")+(Invoer!$C$18:$C$57="Overige ruimte")+(Invoer!$C$18:$C$57="Verkeersruimte"))*(Invoer!$F$18:$F$57="J")*(Invoer!$I$18:$I$57="J")*1/IF(Invoer!$T$18:$T$57=0,1,Invoer!$T$18:$T$57)))+MIN(2,SUMPRODUCT(((Invoer!$C$18:$C$57="Privévertrek")+(Invoer!$C$18:$C$57="Keuken")+(Invoer!$C$18:$C$57="Badruimte"))*(Invoer!$F$18:$F$57="J")*(Invoer!$G$18:$G$57="J")*(Invoer!$I$18:$I$57="J")*1/IF(Invoer!$T$18:$T$57=0,1,Invoer!$T$18:$T$57)))+0.125,0.25) | E5: =FLOOR(SUMPRODUCT(((Invoer!$C$18:$C$57="Privévertrek")+(Invoer!$C$18:$C$57="Keuken")+(Invoer!$C$18:$C$57="Badruimte"))*(Invoer!$F$18:$F$57="J")*(Invoer!$J$18:$J$57="J")*2/IF(Invoer!$T$18:$T$57=0,1,Invoer!$T$18:$T$57))+MIN(4,SUMPRODUCT(((Invoer!$C$18:$C$57="Berging")+(Invoer!$C$18:$C$57="Bijkeuken")+(Invoer!$C$18:$C$57="Wasruimte")+(Invoer!$C$18:$C$57="Overige ruimte")+(Invoer!$C$18:$C$57="Verkeersruimte"))*(Invoer!$F$18:$F$57="J")*(Invoer!$J$18:$J$57="J")*1/IF(Invoer!$T$18:$T$57=0,1,Invoer!$T$18:$T$57)))+MIN(2,SUMPRODUCT(((Invoer!$C$18:$C$57="Privévertrek")+(Invoer!$C$18:$C$57="Keuken")+(Invoer!$C$18:$C$57="Badruimte"))*(Invoer!$F$18:$F$57="J")*(Invoer!$G$18:$G$57="J")*(Invoer!$J$18:$J$57="J")*1/IF(Invoer!$T$18:$T$57=0,1,Invoer!$T$18:$T$57)))+0.125,0.25) | F5: =FLOOR(SUMPRODUCT(((Invoer!$C$18:$C$57="Privévertrek")+(Invoer!$C$18:$C$57="Keuken")+(Invoer!$C$18:$C$57="Badruimte"))*(Invoer!$F$18:$F$57="J")*(Invoer!$K$18:$K$57="J")*2/IF(Invoer!$T$18:$T$57=0,1,Invoer!$T$18:$T$57))+MIN(4,SUMPRODUCT(((Invoer!$C$18:$C$57="Berging")+(Invoer!$C$18:$C$57="Bijkeuken")+(Invoer!$C$18:$C$57="Wasruimte")+(Invoer!$C$18:$C$57="Overige ruimte")+(Invoer!$C$18:$C$57="Verkeersruimte"))*(Invoer!$F$18:$F$57="J")*(Invoer!$K$18:$K$57="J")*1/IF(Invoer!$T$18:$T$57=0,1,Invoer!$T$18:$T$57)))+MIN(2,SUMPRODUCT(((Invoer!$C$18:$C$57="Privévertrek")+(Invoer!$C$18:$C$57="Keuken")+(Invoer!$C$18:$C$57="Badruimte"))*(Invoer!$F$18:$F$57="J")*(Invoer!$G$18:$G$57="J")*(Invoer!$K$18:$K$57="J")*1/IF(Invoer!$T$18:$T$57=0,1,Invoer!$T$18:$T$57)))+0.125,0.25) | G5: =FLOOR(SUMPRODUCT(((Invoer!$C$18:$C$57="Privévertrek")+(Invoer!$C$18:$C$57="Keuken")+(Invoer!$C$18:$C$57="Badruimte"))*(Invoer!$F$18:$F$57="J")*(Invoer!$L$18:$L$57="J")*2/IF(Invoer!$T$18:$T$57=0,1,Invoer!$T$18:$T$57))+MIN(4,SUMPRODUCT(((Invoer!$C$18:$C$57="Berging")+(Invoer!$C$18:$C$57="Bijkeuken")+(Invoer!$C$18:$C$57="Wasruimte")+(Invoer!$C$18:$C$57="Overige ruimte")+(Invoer!$C$18:$C$57="Verkeersruimte"))*(Invoer!$F$18:$F$57="J")*(Invoer!$L$18:$L$57="J")*1/IF(Invoer!$T$18:$T$57=0,1,Invoer!$T$18:$T$57)))+MIN(2,SUMPRODUCT(((Invoer!$C$18:$C$57="Privévertrek")+(Invoer!$C$18:$C$57="Keuken")+(Invoer!$C$18:$C$57="Badruimte"))*(Invoer!$F$18:$F$57="J")*(Invoer!$G$18:$G$57="J")*(Invoer!$L$18:$L$57="J")*1/IF(Invoer!$T$18:$T$57=0,1,Invoer!$T$18:$T$57)))+0.125,0.25) | H5: =FLOOR(SUMPRODUCT(((Invoer!$C$18:$C$57="Privévertrek")+(Invoer!$C$18:$C$57="Keuken")+(Invoer!$C$18:$C$57="Badruimte"))*(Invoer!$F$18:$F$57="J")*(Invoer!$M$18:$M$57="J")*2/IF(Invoer!$T$18:$T$57=0,1,Invoer!$T$18:$T$57))+MIN(4,SUMPRODUCT(((Invoer!$C$18:$C$57="Berging")+(Invoer!$C$18:$C$57="Bijkeuken")+(Invoer!$C$18:$C$57="Wasruimte")+(Invoer!$C$18:$C$57="Overige ruimte")+(Invoer!$C$18:$C$57="Verkeersruimte"))*(Invoer!$F$18:$F$57="J")*(Invoer!$M$18:$M$57="J")*1/IF(Invoer!$T$18:$T$57=0,1,Invoer!$T$18:$T$57)))+MIN(2,SUMPRODUCT(((Invoer!$C$18:$C$57="Privévertrek")+(Invoer!$C$18:$C$57="Keuken")+(Invoer!$C$18:$C$57="Badruimte"))*(Invoer!$F$18:$F$57="J")*(Invoer!$G$18:$G$57="J")*(Invoer!$M$18:$M$57="J")*1/IF(Invoer!$T$18:$T$57=0,1,Invoer!$T$18:$T$57)))+0.125,0.25) | I5: =FLOOR(SUMPRODUCT(((Invoer!$C$18:$C$57="Privévertrek")+(Invoer!$C$18:$C$57="Keuken")+(Invoer!$C$18:$C$57="Badruimte"))*(Invoer!$F$18:$F$57="J")*(Invoer!$N$18:$N$57="J")*2/IF(Invoer!$T$18:$T$57=0,1,Invoer!$T$18:$T$57))+MIN(4,SUMPRODUCT(((Invoer!$C$18:$C$57="Berging")+(Invoer!$C$18:$C$57="Bijkeuken")+(Invoer!$C$18:$C$57="Wasruimte")+(Invoer!$C$18:$C$57="Overige ruimte")+(Invoer!$C$18:$C$57="Verkeersruimte"))*(Invoer!$F$18:$F$57="J")*(Invoer!$N$18:$N$57="J")*1/IF(Invoer!$T$18:$T$57=0,1,Invoer!$T$18:$T$57)))+MIN(2,SUMPRODUCT(((Invoer!$C$18:$C$57="Privévertrek")+(Invoer!$C$18:$C$57="Keuken")+(Invoer!$C$18:$C$57="Badruimte"))*(Invoer!$F$18:$F$57="J")*(Invoer!$G$18:$G$57="J")*(Invoer!$N$18:$N$57="J")*1/IF(Invoer!$T$18:$T$57=0,1,Invoer!$T$18:$T$57)))+0.125,0.25) | J5: =FLOOR(SUMPRODUCT(((Invoer!$C$18:$C$57="Privévertrek")+(Invoer!$C$18:$C$57="Keuken")+(Invoer!$C$18:$C$57="Badruimte"))*(Invoer!$F$18:$F$57="J")*(Invoer!$O$18:$O$57="J")*2/IF(Invoer!$T$18:$T$57=0,1,Invoer!$T$18:$T$57))+MIN(4,SUMPRODUCT(((Invoer!$C$18:$C$57="Berging")+(Invoer!$C$18:$C$57="Bijkeuken")+(Invoer!$C$18:$C$57="Wasruimte")+(Invoer!$C$18:$C$57="Overige ruimte")+(Invoer!$C$18:$C$57="Verkeersruimte"))*(Invoer!$F$18:$F$57="J")*(Invoer!$O$18:$O$57="J")*1/IF(Invoer!$T$18:$T$57=0,1,Invoer!$T$18:$T$57)))+MIN(2,SUMPRODUCT(((Invoer!$C$18:$C$57="Privévertrek")+(Invoer!$C$18:$C$57="Keuken")+(Invoer!$C$18:$C$57="Badruimte"))*(Invoer!$F$18:$F$57="J")*(Invoer!$G$18:$G$57="J")*(Invoer!$O$18:$O$57="J")*1/IF(Invoer!$T$18:$T$57=0,1,Invoer!$T$18:$T$57)))+0.125,0.25) | K5: =FLOOR(SUMPRODUCT(((Invoer!$C$18:$C$57="Privévertrek")+(Invoer!$C$18:$C$57="Keuken")+(Invoer!$C$18:$C$57="Badruimte"))*(Invoer!$F$18:$F$57="J")*(Invoer!$P$18:$P$57="J")*2/IF(Invoer!$T$18:$T$57=0,1,Invoer!$T$18:$T$57))+MIN(4,SUMPRODUCT(((Invoer!$C$18:$C$57="Berging")+(Invoer!$C$18:$C$57="Bijkeuken")+(Invoer!$C$18:$C$57="Wasruimte")+(Invoer!$C$18:$C$57="Overige ruimte")+(Invoer!$C$18:$C$57="Verkeersruimte"))*(Invoer!$F$18:$F$57="J")*(Invoer!$P$18:$P$57="J")*1/IF(Invoer!$T$18:$T$57=0,1,Invoer!$T$18:$T$57)))+MIN(2,SUMPRODUCT(((Invoer!$C$18:$C$57="Privévertrek")+(Invoer!$C$18:$C$57="Keuken")+(Invoer!$C$18:$C$57="Badruimte"))*(Invoer!$F$18:$F$57="J")*(Invoer!$G$18:$G$57="J")*(Invoer!$P$18:$P$57="J")*1/IF(Invoer!$T$18:$T$57=0,1,Invoer!$T$18:$T$57)))+0.125,0.25) | L5: =FLOOR(SUMPRODUCT(((Invoer!$C$18:$C$57="Privévertrek")+(Invoer!$C$18:$C$57="Keuken")+(Invoer!$C$18:$C$57="Badruimte"))*(Invoer!$F$18:$F$57="J")*(Invoer!$Q$18:$Q$57="J")*2/IF(Invoer!$T$18:$T$57=0,1,Invoer!$T$18:$T$57))+MIN(4,SUMPRODUCT(((Invoer!$C$18:$C$57="Berging")+(Invoer!$C$18:$C$57="Bijkeuken")+(Invoer!$C$18:$C$57="Wasruimte")+(Invoer!$C$18:$C$57="Overige ruimte")+(Invoer!$C$18:$C$57="Verkeersruimte"))*(Invoer!$F$18:$F$57="J")*(Invoer!$Q$18:$Q$57="J")*1/IF(Invoer!$T$18:$T$57=0,1,Invoer!$T$18:$T$57)))+MIN(2,SUMPRODUCT(((Invoer!$C$18:$C$57="Privévertrek")+(Invoer!$C$18:$C$57="Keuken")+(Invoer!$C$18:$C$57="Badruimte"))*(Invoer!$F$18:$F$57="J")*(Invoer!$G$18:$G$57="J")*(Invoer!$Q$18:$Q$57="J")*1/IF(Invoer!$T$18:$T$57=0,1,Invoer!$T$18:$T$57)))+0.125,0.25) | M5: =FLOOR(SUMPRODUCT(((Invoer!$C$18:$C$57="Privévertrek")+(Invoer!$C$18:$C$57="Keuken")+(Invoer!$C$18:$C$57="Badruimte"))*(Invoer!$F$18:$F$57="J")*(Invoer!$R$18:$R$57="J")*2/IF(Invoer!$T$18:$T$57=0,1,Invoer!$T$18:$T$57))+MIN(4,SUMPRODUCT(((Invoer!$C$18:$C$57="Berging")+(Invoer!$C$18:$C$57="Bijkeuken")+(Invoer!$C$18:$C$57="Wasruimte")+(Invoer!$C$18:$C$57="Overige ruimte")+(Invoer!$C$18:$C$57="Verkeersruimte"))*(Invoer!$F$18:$F$57="J")*(Invoer!$R$18:$R$57="J")*1/IF(Invoer!$T$18:$T$57=0,1,Invoer!$T$18:$T$57)))+MIN(2,SUMPRODUCT(((Invoer!$C$18:$C$57="Privévertrek")+(Invoer!$C$18:$C$57="Keuken")+(Invoer!$C$18:$C$57="Badruimte"))*(Invoer!$F$18:$F$57="J")*(Invoer!$G$18:$G$57="J")*(Invoer!$R$18:$R$57="J")*1/IF(Invoer!$T$18:$T$57=0,1,Invoer!$T$18:$T$57)))+0.125,0.25) | N5: =FLOOR(SUMPRODUCT(((Invoer!$C$18:$C$57="Privévertrek")+(Invoer!$C$18:$C$57="Keuken")+(Invoer!$C$18:$C$57="Badruimte"))*(Invoer!$F$18:$F$57="J")*(Invoer!$S$18:$S$57="J")*2/IF(Invoer!$T$18:$T$57=0,1,Invoer!$T$18:$T$57))+MIN(4,SUMPRODUCT(((Invoer!$C$18:$C$57="Berging")+(Invoer!$C$18:$C$57="Bijkeuken")+(Invoer!$C$18:$C$57="Wasruimte")+(Invoer!$C$18:$C$57="Overige ruimte")+(Invoer!$C$18:$C$57="Verkeersruimte"))*(Invoer!$F$18:$F$57="J")*(Invoer!$S$18:$S$57="J")*1/IF(Invoer!$T$18:$T$57=0,1,Invoer!$T$18:$T$57)))+MIN(2,SUMPRODUCT(((Invoer!$C$18:$C$57="Privévertrek")+(Invoer!$C$18:$C$57="Keuken")+(Invoer!$C$18:$C$57="Badruimte"))*(Invoer!$F$18:$F$57="J")*(Invoer!$G$18:$G$57="J")*(Invoer!$S$18:$S$57="J")*1/IF(Invoer!$T$18:$T$57=0,1,Invoer!$T$18:$T$57)))+0.125,0.25) | O5: =SUM(C5:N5)
A6: R4 | B6: Energieprestatie (§2.4) | C6: =FLOOR((SUMPRODUCT((Invoer!$C$18:$C$57="Privévertrek")*(Invoer!$H$18:$H$57="J")*Invoer!$D$18:$D$57)+SUMPRODUCT(((Invoer!$C$18:$C$57="Keuken")+(Invoer!$C$18:$C$57="Badruimte"))*(Invoer!$H$18:$H$57="J")*Invoer!$D$18:$D$57/IF(Invoer!$T$18:$T$57=0,1,Invoer!$T$18:$T$57)))*IFERROR(INDEX(tbl_energielabel_fac,MATCH(Invoer!$B$10,tbl_energielabel_lbl,0)),IFERROR(INDEX(tbl_bouwjaar_fac,MATCH(Invoer!$B$12,tbl_bouwjaar_grens,1)),0))+0.125,0.25) | D6: =FLOOR((SUMPRODUCT((Invoer!$C$18:$C$57="Privévertrek")*(Invoer!$I$18:$I$57="J")*Invoer!$D$18:$D$57)+SUMPRODUCT(((Invoer!$C$18:$C$57="Keuken")+(Invoer!$C$18:$C$57="Badruimte"))*(Invoer!$I$18:$I$57="J")*Invoer!$D$18:$D$57/IF(Invoer!$T$18:$T$57=0,1,Invoer!$T$18:$T$57)))*IFERROR(INDEX(tbl_energielabel_fac,MATCH(Invoer!$B$10,tbl_energielabel_lbl,0)),IFERROR(INDEX(tbl_bouwjaar_fac,MATCH(Invoer!$B$12,tbl_bouwjaar_grens,1)),0))+0.125,0.25) | E6: =FLOOR((SUMPRODUCT((Invoer!$C$18:$C$57="Privévertrek")*(Invoer!$J$18:$J$57="J")*Invoer!$D$18:$D$57)+SUMPRODUCT(((Invoer!$C$18:$C$57="Keuken")+(Invoer!$C$18:$C$57="Badruimte"))*(Invoer!$J$18:$J$57="J")*Invoer!$D$18:$D$57/IF(Invoer!$T$18:$T$57=0,1,Invoer!$T$18:$T$57)))*IFERROR(INDEX(tbl_energielabel_fac,MATCH(Invoer!$B$10,tbl_energielabel_lbl,0)),IFERROR(INDEX(tbl_bouwjaar_fac,MATCH(Invoer!$B$12,tbl_bouwjaar_grens,1)),0))+0.125,0.25) | F6: =FLOOR((SUMPRODUCT((Invoer!$C$18:$C$57="Privévertrek")*(Invoer!$K$18:$K$57="J")*Invoer!$D$18:$D$57)+SUMPRODUCT(((Invoer!$C$18:$C$57="Keuken")+(Invoer!$C$18:$C$57="Badruimte"))*(Invoer!$K$18:$K$57="J")*Invoer!$D$18:$D$57/IF(Invoer!$T$18:$T$57=0,1,Invoer!$T$18:$T$57)))*IFERROR(INDEX(tbl_energielabel_fac,MATCH(Invoer!$B$10,tbl_energielabel_lbl,0)),IFERROR(INDEX(tbl_bouwjaar_fac,MATCH(Invoer!$B$12,tbl_bouwjaar_grens,1)),0))+0.125,0.25) | G6: =FLOOR((SUMPRODUCT((Invoer!$C$18:$C$57="Privévertrek")*(Invoer!$L$18:$L$57="J")*Invoer!$D$18:$D$57)+SUMPRODUCT(((Invoer!$C$18:$C$57="Keuken")+(Invoer!$C$18:$C$57="Badruimte"))*(Invoer!$L$18:$L$57="J")*Invoer!$D$18:$D$57/IF(Invoer!$T$18:$T$57=0,1,Invoer!$T$18:$T$57)))*IFERROR(INDEX(tbl_energielabel_fac,MATCH(Invoer!$B$10,tbl_energielabel_lbl,0)),IFERROR(INDEX(tbl_bouwjaar_fac,MATCH(Invoer!$B$12,tbl_bouwjaar_grens,1)),0))+0.125,0.25) | H6: =FLOOR((SUMPRODUCT((Invoer!$C$18:$C$57="Privévertrek")*(Invoer!$M$18:$M$57="J")*Invoer!$D$18:$D$57)+SUMPRODUCT(((Invoer!$C$18:$C$57="Keuken")+(Invoer!$C$18:$C$57="Badruimte"))*(Invoer!$M$18:$M$57="J")*Invoer!$D$18:$D$57/IF(Invoer!$T$18:$T$57=0,1,Invoer!$T$18:$T$57)))*IFERROR(INDEX(tbl_energielabel_fac,MATCH(Invoer!$B$10,tbl_energielabel_lbl,0)),IFERROR(INDEX(tbl_bouwjaar_fac,MATCH(Invoer!$B$12,tbl_bouwjaar_grens,1)),0))+0.125,0.25) | I6: =FLOOR((SUMPRODUCT((Invoer!$C$18:$C$57="Privévertrek")*(Invoer!$N$18:$N$57="J")*Invoer!$D$18:$D$57)+SUMPRODUCT(((Invoer!$C$18:$C$57="Keuken")+(Invoer!$C$18:$C$57="Badruimte"))*(Invoer!$N$18:$N$57="J")*Invoer!$D$18:$D$57/IF(Invoer!$T$18:$T$57=0,1,Invoer!$T$18:$T$57)))*IFERROR(INDEX(tbl_energielabel_fac,MATCH(Invoer!$B$10,tbl_energielabel_lbl,0)),IFERROR(INDEX(tbl_bouwjaar_fac,MATCH(Invoer!$B$12,tbl_bouwjaar_grens,1)),0))+0.125,0.25) | J6: =FLOOR((SUMPRODUCT((Invoer!$C$18:$C$57="Privévertrek")*(Invoer!$O$18:$O$57="J")*Invoer!$D$18:$D$57)+SUMPRODUCT(((Invoer!$C$18:$C$57="Keuken")+(Invoer!$C$18:$C$57="Badruimte"))*(Invoer!$O$18:$O$57="J")*Invoer!$D$18:$D$57/IF(Invoer!$T$18:$T$57=0,1,Invoer!$T$18:$T$57)))*IFERROR(INDEX(tbl_energielabel_fac,MATCH(Invoer!$B$10,tbl_energielabel_lbl,0)),IFERROR(INDEX(tbl_bouwjaar_fac,MATCH(Invoer!$B$12,tbl_bouwjaar_grens,1)),0))+0.125,0.25) | K6: =FLOOR((SUMPRODUCT((Invoer!$C$18:$C$57="Privévertrek")*(Invoer!$P$18:$P$57="J")*Invoer!$D$18:$D$57)+SUMPRODUCT(((Invoer!$C$18:$C$57="Keuken")+(Invoer!$C$18:$C$57="Badruimte"))*(Invoer!$P$18:$P$57="J")*Invoer!$D$18:$D$57/IF(Invoer!$T$18:$T$57=0,1,Invoer!$T$18:$T$57)))*IFERROR(INDEX(tbl_energielabel_fac,MATCH(Invoer!$B$10,tbl_energielabel_lbl,0)),IFERROR(INDEX(tbl_bouwjaar_fac,MATCH(Invoer!$B$12,tbl_bouwjaar_grens,1)),0))+0.125,0.25) | L6: =FLOOR((SUMPRODUCT((Invoer!$C$18:$C$57="Privévertrek")*(Invoer!$Q$18:$Q$57="J")*Invoer!$D$18:$D$57)+SUMPRODUCT(((Invoer!$C$18:$C$57="Keuken")+(Invoer!$C$18:$C$57="Badruimte"))*(Invoer!$Q$18:$Q$57="J")*Invoer!$D$18:$D$57/IF(Invoer!$T$18:$T$57=0,1,Invoer!$T$18:$T$57)))*IFERROR(INDEX(tbl_energielabel_fac,MATCH(Invoer!$B$10,tbl_energielabel_lbl,0)),IFERROR(INDEX(tbl_bouwjaar_fac,MATCH(Invoer!$B$12,tbl_bouwjaar_grens,1)),0))+0.125,0.25) | M6: =FLOOR((SUMPRODUCT((Invoer!$C$18:$C$57="Privévertrek")*(Invoer!$R$18:$R$57="J")*Invoer!$D$18:$D$57)+SUMPRODUCT(((Invoer!$C$18:$C$57="Keuken")+(Invoer!$C$18:$C$57="Badruimte"))*(Invoer!$R$18:$R$57="J")*Invoer!$D$18:$D$57/IF(Invoer!$T$18:$T$57=0,1,Invoer!$T$18:$T$57)))*IFERROR(INDEX(tbl_energielabel_fac,MATCH(Invoer!$B$10,tbl_energielabel_lbl,0)),IFERROR(INDEX(tbl_bouwjaar_fac,MATCH(Invoer!$B$12,tbl_bouwjaar_grens,1)),0))+0.125,0.25) | N6: =FLOOR((SUMPRODUCT((Invoer!$C$18:$C$57="Privévertrek")*(Invoer!$S$18:$S$57="J")*Invoer!$D$18:$D$57)+SUMPRODUCT(((Invoer!$C$18:$C$57="Keuken")+(Invoer!$C$18:$C$57="Badruimte"))*(Invoer!$S$18:$S$57="J")*Invoer!$D$18:$D$57/IF(Invoer!$T$18:$T$57=0,1,Invoer!$T$18:$T$57)))*IFERROR(INDEX(tbl_energielabel_fac,MATCH(Invoer!$B$10,tbl_energielabel_lbl,0)),IFERROR(INDEX(tbl_bouwjaar_fac,MATCH(Invoer!$B$12,tbl_bouwjaar_grens,1)),0))+0.125,0.25) | O6: =SUM(C6:N6)
A7: R5 | B7: Keukenvoorzieningen (§2.5) | C7: =FLOOR(IFERROR(IF(AND(Voorzieningen!$B$4<>"",INDEX(Invoer!$H$18:$S$57,Voorzieningen!$B$4,1)="J"),Voorzieningen!$B$25,0),0)+IFERROR(IF(AND(Voorzieningen!$B$27<>"",INDEX(Invoer!$H$18:$S$57,Voorzieningen!$B$27,1)="J"),Voorzieningen!$B$48,0),0)+IFERROR(IF(AND(Voorzieningen!$B$50<>"",INDEX(Invoer!$H$18:$S$57,Voorzieningen!$B$50,1)="J"),Voorzieningen!$B$71,0),0)+IFERROR(IF(AND(Voorzieningen!$B$73<>"",INDEX(Invoer!$H$18:$S$57,Voorzieningen!$B$73,1)="J"),Voorzieningen!$B$94,0),0)+IFERROR(IF(AND(Voorzieningen!$B$96<>"",INDEX(Invoer!$H$18:$S$57,Voorzieningen!$B$96,1)="J"),Voorzieningen!$B$117,0),0)+IFERROR(IF(AND(Voorzieningen!$B$119<>"",INDEX(Invoer!$H$18:$S$57,Voorzieningen!$B$119,1)="J"),Voorzieningen!$B$140,0),0)+0.125,0.25) | D7: =FLOOR(IFERROR(IF(AND(Voorzieningen!$B$4<>"",INDEX(Invoer!$H$18:$S$57,Voorzieningen!$B$4,2)="J"),Voorzieningen!$B$25,0),0)+IFERROR(IF(AND(Voorzieningen!$B$27<>"",INDEX(Invoer!$H$18:$S$57,Voorzieningen!$B$27,2)="J"),Voorzieningen!$B$48,0),0)+IFERROR(IF(AND(Voorzieningen!$B$50<>"",INDEX(Invoer!$H$18:$S$57,Voorzieningen!$B$50,2)="J"),Voorzieningen!$B$71,0),0)+IFERROR(IF(AND(Voorzieningen!$B$73<>"",INDEX(Invoer!$H$18:$S$57,Voorzieningen!$B$73,2)="J"),Voorzieningen!$B$94,0),0)+IFERROR(IF(AND(Voorzieningen!$B$96<>"",INDEX(Invoer!$H$18:$S$57,Voorzieningen!$B$96,2)="J"),Voorzieningen!$B$117,0),0)+IFERROR(IF(AND(Voorzieningen!$B$119<>"",INDEX(Invoer!$H$18:$S$57,Voorzieningen!$B$119,2)="J"),Voorzieningen!$B$140,0),0)+0.125,0.25) | E7: =FLOOR(IFERROR(IF(AND(Voorzieningen!$B$4<>"",INDEX(Invoer!$H$18:$S$57,Voorzieningen!$B$4,3)="J"),Voorzieningen!$B$25,0),0)+IFERROR(IF(AND(Voorzieningen!$B$27<>"",INDEX(Invoer!$H$18:$S$57,Voorzieningen!$B$27,3)="J"),Voorzieningen!$B$48,0),0)+IFERROR(IF(AND(Voorzieningen!$B$50<>"",INDEX(Invoer!$H$18:$S$57,Voorzieningen!$B$50,3)="J"),Voorzieningen!$B$71,0),0)+IFERROR(IF(AND(Voorzieningen!$B$73<>"",INDEX(Invoer!$H$18:$S$57,Voorzieningen!$B$73,3)="J"),Voorzieningen!$B$94,0),0)+IFERROR(IF(AND(Voorzieningen!$B$96<>"",INDEX(Invoer!$H$18:$S$57,Voorzieningen!$B$96,3)="J"),Voorzieningen!$B$117,0),0)+IFERROR(IF(AND(Voorzieningen!$B$119<>"",INDEX(Invoer!$H$18:$S$57,Voorzieningen!$B$119,3)="J"),Voorzieningen!$B$140,0),0)+0.125,0.25) | F7: =FLOOR(IFERROR(IF(AND(Voorzieningen!$B$4<>"",INDEX(Invoer!$H$18:$S$57,Voorzieningen!$B$4,4)="J"),Voorzieningen!$B$25,0),0)+IFERROR(IF(AND(Voorzieningen!$B$27<>"",INDEX(Invoer!$H$18:$S$57,Voorzieningen!$B$27,4)="J"),Voorzieningen!$B$48,0),0)+IFERROR(IF(AND(Voorzieningen!$B$50<>"",INDEX(Invoer!$H$18:$S$57,Voorzieningen!$B$50,4)="J"),Voorzieningen!$B$71,0),0)+IFERROR(IF(AND(Voorzieningen!$B$73<>"",INDEX(Invoer!$H$18:$S$57,Voorzieningen!$B$73,4)="J"),Voorzieningen!$B$94,0),0)+IFERROR(IF(AND(Voorzieningen!$B$96<>"",INDEX(Invoer!$H$18:$S$57,Voorzieningen!$B$96,4)="J"),Voorzieningen!$B$117,0),0)+IFERROR(IF(AND(Voorzieningen!$B$119<>"",INDEX(Invoer!$H$18:$S$57,Voorzieningen!$B$119,4)="J"),Voorzieningen!$B$140,0),0)+0.125,0.25) | G7: =FLOOR(IFERROR(IF(AND(Voorzieningen!$B$4<>"",INDEX(Invoer!$H$18:$S$57,Voorzieningen!$B$4,5)="J"),Voorzieningen!$B$25,0),0)+IFERROR(IF(AND(Voorzieningen!$B$27<>"",INDEX(Invoer!$H$18:$S$57,Voorzieningen!$B$27,5)="J"),Voorzieningen!$B$48,0),0)+IFERROR(IF(AND(Voorzieningen!$B$50<>"",INDEX(Invoer!$H$18:$S$57,Voorzieningen!$B$50,5)="J"),Voorzieningen!$B$71,0),0)+IFERROR(IF(AND(Voorzieningen!$B$73<>"",INDEX(Invoer!$H$18:$S$57,Voorzieningen!$B$73,5)="J"),Voorzieningen!$B$94,0),0)+IFERROR(IF(AND(Voorzieningen!$B$96<>"",INDEX(Invoer!$H$18:$S$57,Voorzieningen!$B$96,5)="J"),Voorzieningen!$B$117,0),0)+IFERROR(IF(AND(Voorzieningen!$B$119<>"",INDEX(Invoer!$H$18:$S$57,Voorzieningen!$B$119,5)="J"),Voorzieningen!$B$140,0),0)+0.125,0.25) | H7: =FLOOR(IFERROR(IF(AND(Voorzieningen!$B$4<>"",INDEX(Invoer!$H$18:$S$57,Voorzieningen!$B$4,6)="J"),Voorzieningen!$B$25,0),0)+IFERROR(IF(AND(Voorzieningen!$B$27<>"",INDEX(Invoer!$H$18:$S$57,Voorzieningen!$B$27,6)="J"),Voorzieningen!$B$48,0),0)+IFERROR(IF(AND(Voorzieningen!$B$50<>"",INDEX(Invoer!$H$18:$S$57,Voorzieningen!$B$50,6)="J"),Voorzieningen!$B$71,0),0)+IFERROR(IF(AND(Voorzieningen!$B$73<>"",INDEX(Invoer!$H$18:$S$57,Voorzieningen!$B$73,6)="J"),Voorzieningen!$B$94,0),0)+IFERROR(IF(AND(Voorzieningen!$B$96<>"",INDEX(Invoer!$H$18:$S$57,Voorzieningen!$B$96,6)="J"),Voorzieningen!$B$117,0),0)+IFERROR(IF(AND(Voorzieningen!$B$119<>"",INDEX(Invoer!$H$18:$S$57,Voorzieningen!$B$119,6)="J"),Voorzieningen!$B$140,0),0)+0.125,0.25) | I7: =FLOOR(IFERROR(IF(AND(Voorzieningen!$B$4<>"",INDEX(Invoer!$H$18:$S$57,Voorzieningen!$B$4,7)="J"),Voorzieningen!$B$25,0),0)+IFERROR(IF(AND(Voorzieningen!$B$27<>"",INDEX(Invoer!$H$18:$S$57,Voorzieningen!$B$27,7)="J"),Voorzieningen!$B$48,0),0)+IFERROR(IF(AND(Voorzieningen!$B$50<>"",INDEX(Invoer!$H$18:$S$57,Voorzieningen!$B$50,7)="J"),Voorzieningen!$B$71,0),0)+IFERROR(IF(AND(Voorzieningen!$B$73<>"",INDEX(Invoer!$H$18:$S$57,Voorzieningen!$B$73,7)="J"),Voorzieningen!$B$94,0),0)+IFERROR(IF(AND(Voorzieningen!$B$96<>"",INDEX(Invoer!$H$18:$S$57,Voorzieningen!$B$96,7)="J"),Voorzieningen!$B$117,0),0)+IFERROR(IF(AND(Voorzieningen!$B$119<>"",INDEX(Invoer!$H$18:$S$57,Voorzieningen!$B$119,7)="J"),Voorzieningen!$B$140,0),0)+0.125,0.25) | J7: =FLOOR(IFERROR(IF(AND(Voorzieningen!$B$4<>"",INDEX(Invoer!$H$18:$S$57,Voorzieningen!$B$4,8)="J"),Voorzieningen!$B$25,0),0)+IFERROR(IF(AND(Voorzieningen!$B$27<>"",INDEX(Invoer!$H$18:$S$57,Voorzieningen!$B$27,8)="J"),Voorzieningen!$B$48,0),0)+IFERROR(IF(AND(Voorzieningen!$B$50<>"",INDEX(Invoer!$H$18:$S$57,Voorzieningen!$B$50,8)="J"),Voorzieningen!$B$71,0),0)+IFERROR(IF(AND(Voorzieningen!$B$73<>"",INDEX(Invoer!$H$18:$S$57,Voorzieningen!$B$73,8)="J"),Voorzieningen!$B$94,0),0)+IFERROR(IF(AND(Voorzieningen!$B$96<>"",INDEX(Invoer!$H$18:$S$57,Voorzieningen!$B$96,8)="J"),Voorzieningen!$B$117,0),0)+IFERROR(IF(AND(Voorzieningen!$B$119<>"",INDEX(Invoer!$H$18:$S$57,Voorzieningen!$B$119,8)="J"),Voorzieningen!$B$140,0),0)+0.125,0.25) | K7: =FLOOR(IFERROR(IF(AND(Voorzieningen!$B$4<>"",INDEX(Invoer!$H$18:$S$57,Voorzieningen!$B$4,9)="J"),Voorzieningen!$B$25,0),0)+IFERROR(IF(AND(Voorzieningen!$B$27<>"",INDEX(Invoer!$H$18:$S$57,Voorzieningen!$B$27,9)="J"),Voorzieningen!$B$48,0),0)+IFERROR(IF(AND(Voorzieningen!$B$50<>"",INDEX(Invoer!$H$18:$S$57,Voorzieningen!$B$50,9)="J"),Voorzieningen!$B$71,0),0)+IFERROR(IF(AND(Voorzieningen!$B$73<>"",INDEX(Invoer!$H$18:$S$57,Voorzieningen!$B$73,9)="J"),Voorzieningen!$B$94,0),0)+IFERROR(IF(AND(Voorzieningen!$B$96<>"",INDEX(Invoer!$H$18:$S$57,Voorzieningen!$B$96,9)="J"),Voorzieningen!$B$117,0),0)+IFERROR(IF(AND(Voorzieningen!$B$119<>"",INDEX(Invoer!$H$18:$S$57,Voorzieningen!$B$119,9)="J"),Voorzieningen!$B$140,0),0)+0.125,0.25) | L7: =FLOOR(IFERROR(IF(AND(Voorzieningen!$B$4<>"",INDEX(Invoer!$H$18:$S$57,Voorzieningen!$B$4,10)="J"),Voorzieningen!$B$25,0),0)+IFERROR(IF(AND(Voorzieningen!$B$27<>"",INDEX(Invoer!$H$18:$S$57,Voorzieningen!$B$27,10)="J"),Voorzieningen!$B$48,0),0)+IFERROR(IF(AND(Voorzieningen!$B$50<>"",INDEX(Invoer!$H$18:$S$57,Voorzieningen!$B$50,10)="J"),Voorzieningen!$B$71,0),0)+IFERROR(IF(AND(Voorzieningen!$B$73<>"",INDEX(Invoer!$H$18:$S$57,Voorzieningen!$B$73,10)="J"),Voorzieningen!$B$94,0),0)+IFERROR(IF(AND(Voorzieningen!$B$96<>"",INDEX(Invoer!$H$18:$S$57,Voorzieningen!$B$96,10)="J"),Voorzieningen!$B$117,0),0)+IFERROR(IF(AND(Voorzieningen!$B$119<>"",INDEX(Invoer!$H$18:$S$57,Voorzieningen!$B$119,10)="J"),Voorzieningen!$B$140,0),0)+0.125,0.25) | M7: =FLOOR(IFERROR(IF(AND(Voorzieningen!$B$4<>"",INDEX(Invoer!$H$18:$S$57,Voorzieningen!$B$4,11)="J"),Voorzieningen!$B$25,0),0)+IFERROR(IF(AND(Voorzieningen!$B$27<>"",INDEX(Invoer!$H$18:$S$57,Voorzieningen!$B$27,11)="J"),Voorzieningen!$B$48,0),0)+IFERROR(IF(AND(Voorzieningen!$B$50<>"",INDEX(Invoer!$H$18:$S$57,Voorzieningen!$B$50,11)="J"),Voorzieningen!$B$71,0),0)+IFERROR(IF(AND(Voorzieningen!$B$73<>"",INDEX(Invoer!$H$18:$S$57,Voorzieningen!$B$73,11)="J"),Voorzieningen!$B$94,0),0)+IFERROR(IF(AND(Voorzieningen!$B$96<>"",INDEX(Invoer!$H$18:$S$57,Voorzieningen!$B$96,11)="J"),Voorzieningen!$B$117,0),0)+IFERROR(IF(AND(Voorzieningen!$B$119<>"",INDEX(Invoer!$H$18:$S$57,Voorzieningen!$B$119,11)="J"),Voorzieningen!$B$140,0),0)+0.125,0.25) | N7: =FLOOR(IFERROR(IF(AND(Voorzieningen!$B$4<>"",INDEX(Invoer!$H$18:$S$57,Voorzieningen!$B$4,12)="J"),Voorzieningen!$B$25,0),0)+IFERROR(IF(AND(Voorzieningen!$B$27<>"",INDEX(Invoer!$H$18:$S$57,Voorzieningen!$B$27,12)="J"),Voorzieningen!$B$48,0),0)+IFERROR(IF(AND(Voorzieningen!$B$50<>"",INDEX(Invoer!$H$18:$S$57,Voorzieningen!$B$50,12)="J"),Voorzieningen!$B$71,0),0)+IFERROR(IF(AND(Voorzieningen!$B$73<>"",INDEX(Invoer!$H$18:$S$57,Voorzieningen!$B$73,12)="J"),Voorzieningen!$B$94,0),0)+IFERROR(IF(AND(Voorzieningen!$B$96<>"",INDEX(Invoer!$H$18:$S$57,Voorzieningen!$B$96,12)="J"),Voorzieningen!$B$117,0),0)+IFERROR(IF(AND(Voorzieningen!$B$119<>"",INDEX(Invoer!$H$18:$S$57,Voorzieningen!$B$119,12)="J"),Voorzieningen!$B$140,0),0)+0.125,0.25) | O7: =SUM(C7:N7)
A8: R6 | B8: Sanitaire voorzieningen (§2.6) | C8: =FLOOR(IFERROR(IF(AND(Voorzieningen!$B$144<>"",INDEX(Invoer!$H$18:$S$57,Voorzieningen!$B$144,1)="J"),Voorzieningen!$B$166,0),0)+IFERROR(IF(AND(Voorzieningen!$B$168<>"",INDEX(Invoer!$H$18:$S$57,Voorzieningen!$B$168,1)="J"),Voorzieningen!$B$190,0),0)+IFERROR(IF(AND(Voorzieningen!$B$192<>"",INDEX(Invoer!$H$18:$S$57,Voorzieningen!$B$192,1)="J"),Voorzieningen!$B$214,0),0)+IFERROR(IF(AND(Voorzieningen!$B$216<>"",INDEX(Invoer!$H$18:$S$57,Voorzieningen!$B$216,1)="J"),Voorzieningen!$B$238,0),0)+IFERROR(IF(AND(Voorzieningen!$B$240<>"",INDEX(Invoer!$H$18:$S$57,Voorzieningen!$B$240,1)="J"),Voorzieningen!$B$262,0),0)+IFERROR(IF(AND(Voorzieningen!$B$264<>"",INDEX(Invoer!$H$18:$S$57,Voorzieningen!$B$264,1)="J"),Voorzieningen!$B$286,0),0)+0.125,0.25) | D8: =FLOOR(IFERROR(IF(AND(Voorzieningen!$B$144<>"",INDEX(Invoer!$H$18:$S$57,Voorzieningen!$B$144,2)="J"),Voorzieningen!$B$166,0),0)+IFERROR(IF(AND(Voorzieningen!$B$168<>"",INDEX(Invoer!$H$18:$S$57,Voorzieningen!$B$168,2)="J"),Voorzieningen!$B$190,0),0)+IFERROR(IF(AND(Voorzieningen!$B$192<>"",INDEX(Invoer!$H$18:$S$57,Voorzieningen!$B$192,2)="J"),Voorzieningen!$B$214,0),0)+IFERROR(IF(AND(Voorzieningen!$B$216<>"",INDEX(Invoer!$H$18:$S$57,Voorzieningen!$B$216,2)="J"),Voorzieningen!$B$238,0),0)+IFERROR(IF(AND(Voorzieningen!$B$240<>"",INDEX(Invoer!$H$18:$S$57,Voorzieningen!$B$240,2)="J"),Voorzieningen!$B$262,0),0)+IFERROR(IF(AND(Voorzieningen!$B$264<>"",INDEX(Invoer!$H$18:$S$57,Voorzieningen!$B$264,2)="J"),Voorzieningen!$B$286,0),0)+0.125,0.25) | E8: =FLOOR(IFERROR(IF(AND(Voorzieningen!$B$144<>"",INDEX(Invoer!$H$18:$S$57,Voorzieningen!$B$144,3)="J"),Voorzieningen!$B$166,0),0)+IFERROR(IF(AND(Voorzieningen!$B$168<>"",INDEX(Invoer!$H$18:$S$57,Voorzieningen!$B$168,3)="J"),Voorzieningen!$B$190,0),0)+IFERROR(IF(AND(Voorzieningen!$B$192<>"",INDEX(Invoer!$H$18:$S$57,Voorzieningen!$B$192,3)="J"),Voorzieningen!$B$214,0),0)+IFERROR(IF(AND(Voorzieningen!$B$216<>"",INDEX(Invoer!$H$18:$S$57,Voorzieningen!$B$216,3)="J"),Voorzieningen!$B$238,0),0)+IFERROR(IF(AND(Voorzieningen!$B$240<>"",INDEX(Invoer!$H$18:$S$57,Voorzieningen!$B$240,3)="J"),Voorzieningen!$B$262,0),0)+IFERROR(IF(AND(Voorzieningen!$B$264<>"",INDEX(Invoer!$H$18:$S$57,Voorzieningen!$B$264,3)="J"),Voorzieningen!$B$286,0),0)+0.125,0.25) | F8: =FLOOR(IFERROR(IF(AND(Voorzieningen!$B$144<>"",INDEX(Invoer!$H$18:$S$57,Voorzieningen!$B$144,4)="J"),Voorzieningen!$B$166,0),0)+IFERROR(IF(AND(Voorzieningen!$B$168<>"",INDEX(Invoer!$H$18:$S$57,Voorzieningen!$B$168,4)="J"),Voorzieningen!$B$190,0),0)+IFERROR(IF(AND(Voorzieningen!$B$192<>"",INDEX(Invoer!$H$18:$S$57,Voorzieningen!$B$192,4)="J"),Voorzieningen!$B$214,0),0)+IFERROR(IF(AND(Voorzieningen!$B$216<>"",INDEX(Invoer!$H$18:$S$57,Voorzieningen!$B$216,4)="J"),Voorzieningen!$B$238,0),0)+IFERROR(IF(AND(Voorzieningen!$B$240<>"",INDEX(Invoer!$H$18:$S$57,Voorzieningen!$B$240,4)="J"),Voorzieningen!$B$262,0),0)+IFERROR(IF(AND(Voorzieningen!$B$264<>"",INDEX(Invoer!$H$18:$S$57,Voorzieningen!$B$264,4)="J"),Voorzieningen!$B$286,0),0)+0.125,0.25) | G8: =FLOOR(IFERROR(IF(AND(Voorzieningen!$B$144<>"",INDEX(Invoer!$H$18:$S$57,Voorzieningen!$B$144,5)="J"),Voorzieningen!$B$166,0),0)+IFERROR(IF(AND(Voorzieningen!$B$168<>"",INDEX(Invoer!$H$18:$S$57,Voorzieningen!$B$168,5)="J"),Voorzieningen!$B$190,0),0)+IFERROR(IF(AND(Voorzieningen!$B$192<>"",INDEX(Invoer!$H$18:$S$57,Voorzieningen!$B$192,5)="J"),Voorzieningen!$B$214,0),0)+IFERROR(IF(AND(Voorzieningen!$B$216<>"",INDEX(Invoer!$H$18:$S$57,Voorzieningen!$B$216,5)="J"),Voorzieningen!$B$238,0),0)+IFERROR(IF(AND(Voorzieningen!$B$240<>"",INDEX(Invoer!$H$18:$S$57,Voorzieningen!$B$240,5)="J"),Voorzieningen!$B$262,0),0)+IFERROR(IF(AND(Voorzieningen!$B$264<>"",INDEX(Invoer!$H$18:$S$57,Voorzieningen!$B$264,5)="J"),Voorzieningen!$B$286,0),0)+0.125,0.25) | H8: =FLOOR(IFERROR(IF(AND(Voorzieningen!$B$144<>"",INDEX(Invoer!$H$18:$S$57,Voorzieningen!$B$144,6)="J"),Voorzieningen!$B$166,0),0)+IFERROR(IF(AND(Voorzieningen!$B$168<>"",INDEX(Invoer!$H$18:$S$57,Voorzieningen!$B$168,6)="J"),Voorzieningen!$B$190,0),0)+IFERROR(IF(AND(Voorzieningen!$B$192<>"",INDEX(Invoer!$H$18:$S$57,Voorzieningen!$B$192,6)="J"),Voorzieningen!$B$214,0),0)+IFERROR(IF(AND(Voorzieningen!$B$216<>"",INDEX(Invoer!$H$18:$S$57,Voorzieningen!$B$216,6)="J"),Voorzieningen!$B$238,0),0)+IFERROR(IF(AND(Voorzieningen!$B$240<>"",INDEX(Invoer!$H$18:$S$57,Voorzieningen!$B$240,6)="J"),Voorzieningen!$B$262,0),0)+IFERROR(IF(AND(Voorzieningen!$B$264<>"",INDEX(Invoer!$H$18:$S$57,Voorzieningen!$B$264,6)="J"),Voorzieningen!$B$286,0),0)+0.125,0.25) | I8: =FLOOR(IFERROR(IF(AND(Voorzieningen!$B$144<>"",INDEX(Invoer!$H$18:$S$57,Voorzieningen!$B$144,7)="J"),Voorzieningen!$B$166,0),0)+IFERROR(IF(AND(Voorzieningen!$B$168<>"",INDEX(Invoer!$H$18:$S$57,Voorzieningen!$B$168,7)="J"),Voorzieningen!$B$190,0),0)+IFERROR(IF(AND(Voorzieningen!$B$192<>"",INDEX(Invoer!$H$18:$S$57,Voorzieningen!$B$192,7)="J"),Voorzieningen!$B$214,0),0)+IFERROR(IF(AND(Voorzieningen!$B$216<>"",INDEX(Invoer!$H$18:$S$57,Voorzieningen!$B$216,7)="J"),Voorzieningen!$B$238,0),0)+IFERROR(IF(AND(Voorzieningen!$B$240<>"",INDEX(Invoer!$H$18:$S$57,Voorzieningen!$B$240,7)="J"),Voorzieningen!$B$262,0),0)+IFERROR(IF(AND(Voorzieningen!$B$264<>"",INDEX(Invoer!$H$18:$S$57,Voorzieningen!$B$264,7)="J"),Voorzieningen!$B$286,0),0)+0.125,0.25) | J8: =FLOOR(IFERROR(IF(AND(Voorzieningen!$B$144<>"",INDEX(Invoer!$H$18:$S$57,Voorzieningen!$B$144,8)="J"),Voorzieningen!$B$166,0),0)+IFERROR(IF(AND(Voorzieningen!$B$168<>"",INDEX(Invoer!$H$18:$S$57,Voorzieningen!$B$168,8)="J"),Voorzieningen!$B$190,0),0)+IFERROR(IF(AND(Voorzieningen!$B$192<>"",INDEX(Invoer!$H$18:$S$57,Voorzieningen!$B$192,8)="J"),Voorzieningen!$B$214,0),0)+IFERROR(IF(AND(Voorzieningen!$B$216<>"",INDEX(Invoer!$H$18:$S$57,Voorzieningen!$B$216,8)="J"),Voorzieningen!$B$238,0),0)+IFERROR(IF(AND(Voorzieningen!$B$240<>"",INDEX(Invoer!$H$18:$S$57,Voorzieningen!$B$240,8)="J"),Voorzieningen!$B$262,0),0)+IFERROR(IF(AND(Voorzieningen!$B$264<>"",INDEX(Invoer!$H$18:$S$57,Voorzieningen!$B$264,8)="J"),Voorzieningen!$B$286,0),0)+0.125,0.25) | K8: =FLOOR(IFERROR(IF(AND(Voorzieningen!$B$144<>"",INDEX(Invoer!$H$18:$S$57,Voorzieningen!$B$144,9)="J"),Voorzieningen!$B$166,0),0)+IFERROR(IF(AND(Voorzieningen!$B$168<>"",INDEX(Invoer!$H$18:$S$57,Voorzieningen!$B$168,9)="J"),Voorzieningen!$B$190,0),0)+IFERROR(IF(AND(Voorzieningen!$B$192<>"",INDEX(Invoer!$H$18:$S$57,Voorzieningen!$B$192,9)="J"),Voorzieningen!$B$214,0),0)+IFERROR(IF(AND(Voorzieningen!$B$216<>"",INDEX(Invoer!$H$18:$S$57,Voorzieningen!$B$216,9)="J"),Voorzieningen!$B$238,0),0)+IFERROR(IF(AND(Voorzieningen!$B$240<>"",INDEX(Invoer!$H$18:$S$57,Voorzieningen!$B$240,9)="J"),Voorzieningen!$B$262,0),0)+IFERROR(IF(AND(Voorzieningen!$B$264<>"",INDEX(Invoer!$H$18:$S$57,Voorzieningen!$B$264,9)="J"),Voorzieningen!$B$286,0),0)+0.125,0.25) | L8: =FLOOR(IFERROR(IF(AND(Voorzieningen!$B$144<>"",INDEX(Invoer!$H$18:$S$57,Voorzieningen!$B$144,10)="J"),Voorzieningen!$B$166,0),0)+IFERROR(IF(AND(Voorzieningen!$B$168<>"",INDEX(Invoer!$H$18:$S$57,Voorzieningen!$B$168,10)="J"),Voorzieningen!$B$190,0),0)+IFERROR(IF(AND(Voorzieningen!$B$192<>"",INDEX(Invoer!$H$18:$S$57,Voorzieningen!$B$192,10)="J"),Voorzieningen!$B$214,0),0)+IFERROR(IF(AND(Voorzieningen!$B$216<>"",INDEX(Invoer!$H$18:$S$57,Voorzieningen!$B$216,10)="J"),Voorzieningen!$B$238,0),0)+IFERROR(IF(AND(Voorzieningen!$B$240<>"",INDEX(Invoer!$H$18:$S$57,Voorzieningen!$B$240,10)="J"),Voorzieningen!$B$262,0),0)+IFERROR(IF(AND(Voorzieningen!$B$264<>"",INDEX(Invoer!$H$18:$S$57,Voorzieningen!$B$264,10)="J"),Voorzieningen!$B$286,0),0)+0.125,0.25) | M8: =FLOOR(IFERROR(IF(AND(Voorzieningen!$B$144<>"",INDEX(Invoer!$H$18:$S$57,Voorzieningen!$B$144,11)="J"),Voorzieningen!$B$166,0),0)+IFERROR(IF(AND(Voorzieningen!$B$168<>"",INDEX(Invoer!$H$18:$S$57,Voorzieningen!$B$168,11)="J"),Voorzieningen!$B$190,0),0)+IFERROR(IF(AND(Voorzieningen!$B$192<>"",INDEX(Invoer!$H$18:$S$57,Voorzieningen!$B$192,11)="J"),Voorzieningen!$B$214,0),0)+IFERROR(IF(AND(Voorzieningen!$B$216<>"",INDEX(Invoer!$H$18:$S$57,Voorzieningen!$B$216,11)="J"),Voorzieningen!$B$238,0),0)+IFERROR(IF(AND(Voorzieningen!$B$240<>"",INDEX(Invoer!$H$18:$S$57,Voorzieningen!$B$240,11)="J"),Voorzieningen!$B$262,0),0)+IFERROR(IF(AND(Voorzieningen!$B$264<>"",INDEX(Invoer!$H$18:$S$57,Voorzieningen!$B$264,11)="J"),Voorzieningen!$B$286,0),0)+0.125,0.25) | N8: =FLOOR(IFERROR(IF(AND(Voorzieningen!$B$144<>"",INDEX(Invoer!$H$18:$S$57,Voorzieningen!$B$144,12)="J"),Voorzieningen!$B$166,0),0)+IFERROR(IF(AND(Voorzieningen!$B$168<>"",INDEX(Invoer!$H$18:$S$57,Voorzieningen!$B$168,12)="J"),Voorzieningen!$B$190,0),0)+IFERROR(IF(AND(Voorzieningen!$B$192<>"",INDEX(Invoer!$H$18:$S$57,Voorzieningen!$B$192,12)="J"),Voorzieningen!$B$214,0),0)+IFERROR(IF(AND(Voorzieningen!$B$216<>"",INDEX(Invoer!$H$18:$S$57,Voorzieningen!$B$216,12)="J"),Voorzieningen!$B$238,0),0)+IFERROR(IF(AND(Voorzieningen!$B$240<>"",INDEX(Invoer!$H$18:$S$57,Voorzieningen!$B$240,12)="J"),Voorzieningen!$B$262,0),0)+IFERROR(IF(AND(Voorzieningen!$B$264<>"",INDEX(Invoer!$H$18:$S$57,Voorzieningen!$B$264,12)="J"),Voorzieningen!$B$286,0),0)+0.125,0.25) | O8: =SUM(C8:N8)
A9: R7 | B9: Gemeenschappelijke vertrekken (§2.7) [handmatig] | C9: =0 | D9: =0 | E9: =0 | F9: =0 | G9: =0 | H9: =0 | I9: =0 | J9: =0 | ... N9: =0 | O9: =SUM(C9:N9)
A10: R8 | B10: Buitenruimten (§2.8) | C10: =FLOOR(MIN(15,SUMPRODUCT((Invoer!$C$18:$C$57="Buitenruimte privé")*(Invoer!$H$18:$H$57="J")*(2+0.35*Invoer!$D$18:$D$57)/IF(Invoer!$T$18:$T$57=0,1,Invoer!$T$18:$T$57))+SUMPRODUCT((Invoer!$C$18:$C$57="Buitenruimte gemeenschappelijk")*(Invoer!$H$18:$H$57="J")*0.75*Invoer!$D$18:$D$57/IF(Invoer!$T$18:$T$57=0,1,Invoer!$T$18:$T$57)/IF(Invoer!$B$15=0,1,Invoer!$B$15)))+0.125,0.25) | D10: =FLOOR(MIN(15,SUMPRODUCT((Invoer!$C$18:$C$57="Buitenruimte privé")*(Invoer!$I$18:$I$57="J")*(2+0.35*Invoer!$D$18:$D$57)/IF(Invoer!$T$18:$T$57=0,1,Invoer!$T$18:$T$57))+SUMPRODUCT((Invoer!$C$18:$C$57="Buitenruimte gemeenschappelijk")*(Invoer!$I$18:$I$57="J")*0.75*Invoer!$D$18:$D$57/IF(Invoer!$T$18:$T$57=0,1,Invoer!$T$18:$T$57)/IF(Invoer!$B$15=0,1,Invoer!$B$15)))+0.125,0.25) | E10: =FLOOR(MIN(15,SUMPRODUCT((Invoer!$C$18:$C$57="Buitenruimte privé")*(Invoer!$J$18:$J$57="J")*(2+0.35*Invoer!$D$18:$D$57)/IF(Invoer!$T$18:$T$57=0,1,Invoer!$T$18:$T$57))+SUMPRODUCT((Invoer!$C$18:$C$57="Buitenruimte gemeenschappelijk")*(Invoer!$J$18:$J$57="J")*0.75*Invoer!$D$18:$D$57/IF(Invoer!$T$18:$T$57=0,1,Invoer!$T$18:$T$57)/IF(Invoer!$B$15=0,1,Invoer!$B$15)))+0.125,0.25) | F10: =FLOOR(MIN(15,SUMPRODUCT((Invoer!$C$18:$C$57="Buitenruimte privé")*(Invoer!$K$18:$K$57="J")*(2+0.35*Invoer!$D$18:$D$57)/IF(Invoer!$T$18:$T$57=0,1,Invoer!$T$18:$T$57))+SUMPRODUCT((Invoer!$C$18:$C$57="Buitenruimte gemeenschappelijk")*(Invoer!$K$18:$K$57="J")*0.75*Invoer!$D$18:$D$57/IF(Invoer!$T$18:$T$57=0,1,Invoer!$T$18:$T$57)/IF(Invoer!$B$15=0,1,Invoer!$B$15)))+0.125,0.25) | G10: =FLOOR(MIN(15,SUMPRODUCT((Invoer!$C$18:$C$57="Buitenruimte privé")*(Invoer!$L$18:$L$57="J")*(2+0.35*Invoer!$D$18:$D$57)/IF(Invoer!$T$18:$T$57=0,1,Invoer!$T$18:$T$57))+SUMPRODUCT((Invoer!$C$18:$C$57="Buitenruimte gemeenschappelijk")*(Invoer!$L$18:$L$57="J")*0.75*Invoer!$D$18:$D$57/IF(Invoer!$T$18:$T$57=0,1,Invoer!$T$18:$T$57)/IF(Invoer!$B$15=0,1,Invoer!$B$15)))+0.125,0.25) | H10: =FLOOR(MIN(15,SUMPRODUCT((Invoer!$C$18:$C$57="Buitenruimte privé")*(Invoer!$M$18:$M$57="J")*(2+0.35*Invoer!$D$18:$D$57)/IF(Invoer!$T$18:$T$57=0,1,Invoer!$T$18:$T$57))+SUMPRODUCT((Invoer!$C$18:$C$57="Buitenruimte gemeenschappelijk")*(Invoer!$M$18:$M$57="J")*0.75*Invoer!$D$18:$D$57/IF(Invoer!$T$18:$T$57=0,1,Invoer!$T$18:$T$57)/IF(Invoer!$B$15=0,1,Invoer!$B$15)))+0.125,0.25) | I10: =FLOOR(MIN(15,SUMPRODUCT((Invoer!$C$18:$C$57="Buitenruimte privé")*(Invoer!$N$18:$N$57="J")*(2+0.35*Invoer!$D$18:$D$57)/IF(Invoer!$T$18:$T$57=0,1,Invoer!$T$18:$T$57))+SUMPRODUCT((Invoer!$C$18:$C$57="Buitenruimte gemeenschappelijk")*(Invoer!$N$18:$N$57="J")*0.75*Invoer!$D$18:$D$57/IF(Invoer!$T$18:$T$57=0,1,Invoer!$T$18:$T$57)/IF(Invoer!$B$15=0,1,Invoer!$B$15)))+0.125,0.25) | J10: =FLOOR(MIN(15,SUMPRODUCT((Invoer!$C$18:$C$57="Buitenruimte privé")*(Invoer!$O$18:$O$57="J")*(2+0.35*Invoer!$D$18:$D$57)/IF(Invoer!$T$18:$T$57=0,1,Invoer!$T$18:$T$57))+SUMPRODUCT((Invoer!$C$18:$C$57="Buitenruimte gemeenschappelijk")*(Invoer!$O$18:$O$57="J")*0.75*Invoer!$D$18:$D$57/IF(Invoer!$T$18:$T$57=0,1,Invoer!$T$18:$T$57)/IF(Invoer!$B$15=0,1,Invoer!$B$15)))+0.125,0.25) | K10: =FLOOR(MIN(15,SUMPRODUCT((Invoer!$C$18:$C$57="Buitenruimte privé")*(Invoer!$P$18:$P$57="J")*(2+0.35*Invoer!$D$18:$D$57)/IF(Invoer!$T$18:$T$57=0,1,Invoer!$T$18:$T$57))+SUMPRODUCT((Invoer!$C$18:$C$57="Buitenruimte gemeenschappelijk")*(Invoer!$P$18:$P$57="J")*0.75*Invoer!$D$18:$D$57/IF(Invoer!$T$18:$T$57=0,1,Invoer!$T$18:$T$57)/IF(Invoer!$B$15=0,1,Invoer!$B$15)))+0.125,0.25) | L10: =FLOOR(MIN(15,SUMPRODUCT((Invoer!$C$18:$C$57="Buitenruimte privé")*(Invoer!$Q$18:$Q$57="J")*(2+0.35*Invoer!$D$18:$D$57)/IF(Invoer!$T$18:$T$57=0,1,Invoer!$T$18:$T$57))+SUMPRODUCT((Invoer!$C$18:$C$57="Buitenruimte gemeenschappelijk")*(Invoer!$Q$18:$Q$57="J")*0.75*Invoer!$D$18:$D$57/IF(Invoer!$T$18:$T$57=0,1,Invoer!$T$18:$T$57)/IF(Invoer!$B$15=0,1,Invoer!$B$15)))+0.125,0.25) | M10: =FLOOR(MIN(15,SUMPRODUCT((Invoer!$C$18:$C$57="Buitenruimte privé")*(Invoer!$R$18:$R$57="J")*(2+0.35*Invoer!$D$18:$D$57)/IF(Invoer!$T$18:$T$57=0,1,Invoer!$T$18:$T$57))+SUMPRODUCT((Invoer!$C$18:$C$57="Buitenruimte gemeenschappelijk")*(Invoer!$R$18:$R$57="J")*0.75*Invoer!$D$18:$D$57/IF(Invoer!$T$18:$T$57=0,1,Invoer!$T$18:$T$57)/IF(Invoer!$B$15=0,1,Invoer!$B$15)))+0.125,0.25) | N10: =FLOOR(MIN(15,SUMPRODUCT((Invoer!$C$18:$C$57="Buitenruimte privé")*(Invoer!$S$18:$S$57="J")*(2+0.35*Invoer!$D$18:$D$57)/IF(Invoer!$T$18:$T$57=0,1,Invoer!$T$18:$T$57))+SUMPRODUCT((Invoer!$C$18:$C$57="Buitenruimte gemeenschappelijk")*(Invoer!$S$18:$S$57="J")*0.75*Invoer!$D$18:$D$57/IF(Invoer!$T$18:$T$57=0,1,Invoer!$T$18:$T$57)/IF(Invoer!$B$15=0,1,Invoer!$B$15)))+0.125,0.25) | O10: =SUM(C10:N10)
A11: R9 | B11: Gemeenschappelijke parkeerruimte (§2.9) | C11: =FLOOR(SUMPRODUCT((Invoer!$C$18:$C$57="Gemeenschappelijk vertrek")*(Invoer!$H$18:$H$57="J")*Invoer!$D$18:$D$57*1/IF(Invoer!$T$18:$T$57=0,1,Invoer!$T$18:$T$57)/IF(Invoer!$B$15=0,1,Invoer!$B$15))+SUMPRODUCT((Invoer!$C$18:$C$57="Gemeenschappelijke overige ruimte")*(Invoer!$H$18:$H$57="J")*Invoer!$D$18:$D$57*0.75/IF(Invoer!$T$18:$T$57=0,1,Invoer!$T$18:$T$57)/IF(Invoer!$B$15=0,1,Invoer!$B$15))+0.125,0.25) | D11: =FLOOR(SUMPRODUCT((Invoer!$C$18:$C$57="Gemeenschappelijk vertrek")*(Invoer!$I$18:$I$57="J")*Invoer!$D$18:$D$57*1/IF(Invoer!$T$18:$T$57=0,1,Invoer!$T$18:$T$57)/IF(Invoer!$B$15=0,1,Invoer!$B$15))+SUMPRODUCT((Invoer!$C$18:$C$57="Gemeenschappelijke overige ruimte")*(Invoer!$I$18:$I$57="J")*Invoer!$D$18:$D$57*0.75/IF(Invoer!$T$18:$T$57=0,1,Invoer!$T$18:$T$57)/IF(Invoer!$B$15=0,1,Invoer!$B$15))+0.125,0.25) | E11: =FLOOR(SUMPRODUCT((Invoer!$C$18:$C$57="Gemeenschappelijk vertrek")*(Invoer!$J$18:$J$57="J")*Invoer!$D$18:$D$57*1/IF(Invoer!$T$18:$T$57=0,1,Invoer!$T$18:$T$57)/IF(Invoer!$B$15=0,1,Invoer!$B$15))+SUMPRODUCT((Invoer!$C$18:$C$57="Gemeenschappelijke overige ruimte")*(Invoer!$J$18:$J$57="J")*Invoer!$D$18:$D$57*0.75/IF(Invoer!$T$18:$T$57=0,1,Invoer!$T$18:$T$57)/IF(Invoer!$B$15=0,1,Invoer!$B$15))+0.125,0.25) | F11: =FLOOR(SUMPRODUCT((Invoer!$C$18:$C$57="Gemeenschappelijk vertrek")*(Invoer!$K$18:$K$57="J")*Invoer!$D$18:$D$57*1/IF(Invoer!$T$18:$T$57=0,1,Invoer!$T$18:$T$57)/IF(Invoer!$B$15=0,1,Invoer!$B$15))+SUMPRODUCT((Invoer!$C$18:$C$57="Gemeenschappelijke overige ruimte")*(Invoer!$K$18:$K$57="J")*Invoer!$D$18:$D$57*0.75/IF(Invoer!$T$18:$T$57=0,1,Invoer!$T$18:$T$57)/IF(Invoer!$B$15=0,1,Invoer!$B$15))+0.125,0.25) | G11: =FLOOR(SUMPRODUCT((Invoer!$C$18:$C$57="Gemeenschappelijk vertrek")*(Invoer!$L$18:$L$57="J")*Invoer!$D$18:$D$57*1/IF(Invoer!$T$18:$T$57=0,1,Invoer!$T$18:$T$57)/IF(Invoer!$B$15=0,1,Invoer!$B$15))+SUMPRODUCT((Invoer!$C$18:$C$57="Gemeenschappelijke overige ruimte")*(Invoer!$L$18:$L$57="J")*Invoer!$D$18:$D$57*0.75/IF(Invoer!$T$18:$T$57=0,1,Invoer!$T$18:$T$57)/IF(Invoer!$B$15=0,1,Invoer!$B$15))+0.125,0.25) | H11: =FLOOR(SUMPRODUCT((Invoer!$C$18:$C$57="Gemeenschappelijk vertrek")*(Invoer!$M$18:$M$57="J")*Invoer!$D$18:$D$57*1/IF(Invoer!$T$18:$T$57=0,1,Invoer!$T$18:$T$57)/IF(Invoer!$B$15=0,1,Invoer!$B$15))+SUMPRODUCT((Invoer!$C$18:$C$57="Gemeenschappelijke overige ruimte")*(Invoer!$M$18:$M$57="J")*Invoer!$D$18:$D$57*0.75/IF(Invoer!$T$18:$T$57=0,1,Invoer!$T$18:$T$57)/IF(Invoer!$B$15=0,1,Invoer!$B$15))+0.125,0.25) | I11: =FLOOR(SUMPRODUCT((Invoer!$C$18:$C$57="Gemeenschappelijk vertrek")*(Invoer!$N$18:$N$57="J")*Invoer!$D$18:$D$57*1/IF(Invoer!$T$18:$T$57=0,1,Invoer!$T$18:$T$57)/IF(Invoer!$B$15=0,1,Invoer!$B$15))+SUMPRODUCT((Invoer!$C$18:$C$57="Gemeenschappelijke overige ruimte")*(Invoer!$N$18:$N$57="J")*Invoer!$D$18:$D$57*0.75/IF(Invoer!$T$18:$T$57=0,1,Invoer!$T$18:$T$57)/IF(Invoer!$B$15=0,1,Invoer!$B$15))+0.125,0.25) | J11: =FLOOR(SUMPRODUCT((Invoer!$C$18:$C$57="Gemeenschappelijk vertrek")*(Invoer!$O$18:$O$57="J")*Invoer!$D$18:$D$57*1/IF(Invoer!$T$18:$T$57=0,1,Invoer!$T$18:$T$57)/IF(Invoer!$B$15=0,1,Invoer!$B$15))+SUMPRODUCT((Invoer!$C$18:$C$57="Gemeenschappelijke overige ruimte")*(Invoer!$O$18:$O$57="J")*Invoer!$D$18:$D$57*0.75/IF(Invoer!$T$18:$T$57=0,1,Invoer!$T$18:$T$57)/IF(Invoer!$B$15=0,1,Invoer!$B$15))+0.125,0.25) | K11: =FLOOR(SUMPRODUCT((Invoer!$C$18:$C$57="Gemeenschappelijk vertrek")*(Invoer!$P$18:$P$57="J")*Invoer!$D$18:$D$57*1/IF(Invoer!$T$18:$T$57=0,1,Invoer!$T$18:$T$57)/IF(Invoer!$B$15=0,1,Invoer!$B$15))+SUMPRODUCT((Invoer!$C$18:$C$57="Gemeenschappelijke overige ruimte")*(Invoer!$P$18:$P$57="J")*Invoer!$D$18:$D$57*0.75/IF(Invoer!$T$18:$T$57=0,1,Invoer!$T$18:$T$57)/IF(Invoer!$B$15=0,1,Invoer!$B$15))+0.125,0.25) | L11: =FLOOR(SUMPRODUCT((Invoer!$C$18:$C$57="Gemeenschappelijk vertrek")*(Invoer!$Q$18:$Q$57="J")*Invoer!$D$18:$D$57*1/IF(Invoer!$T$18:$T$57=0,1,Invoer!$T$18:$T$57)/IF(Invoer!$B$15=0,1,Invoer!$B$15))+SUMPRODUCT((Invoer!$C$18:$C$57="Gemeenschappelijke overige ruimte")*(Invoer!$Q$18:$Q$57="J")*Invoer!$D$18:$D$57*0.75/IF(Invoer!$T$18:$T$57=0,1,Invoer!$T$18:$T$57)/IF(Invoer!$B$15=0,1,Invoer!$B$15))+0.125,0.25) | M11: =FLOOR(SUMPRODUCT((Invoer!$C$18:$C$57="Gemeenschappelijk vertrek")*(Invoer!$R$18:$R$57="J")*Invoer!$D$18:$D$57*1/IF(Invoer!$T$18:$T$57=0,1,Invoer!$T$18:$T$57)/IF(Invoer!$B$15=0,1,Invoer!$B$15))+SUMPRODUCT((Invoer!$C$18:$C$57="Gemeenschappelijke overige ruimte")*(Invoer!$R$18:$R$57="J")*Invoer!$D$18:$D$57*0.75/IF(Invoer!$T$18:$T$57=0,1,Invoer!$T$18:$T$57)/IF(Invoer!$B$15=0,1,Invoer!$B$15))+0.125,0.25) | N11: =FLOOR(SUMPRODUCT((Invoer!$C$18:$C$57="Gemeenschappelijk vertrek")*(Invoer!$S$18:$S$57="J")*Invoer!$D$18:$D$57*1/IF(Invoer!$T$18:$T$57=0,1,Invoer!$T$18:$T$57)/IF(Invoer!$B$15=0,1,Invoer!$B$15))+SUMPRODUCT((Invoer!$C$18:$C$57="Gemeenschappelijke overige ruimte")*(Invoer!$S$18:$S$57="J")*Invoer!$D$18:$D$57*0.75/IF(Invoer!$T$18:$T$57=0,1,Invoer!$T$18:$T$57)/IF(Invoer!$B$15=0,1,Invoer!$B$15))+0.125,0.25) | O11: =SUM(C11:N11)
A12: R10 | B12: Parkeren (§2.10) | C12: =FLOOR(Voorzieningen!$B$306+0.125,0.25) | D12: =FLOOR(Voorzieningen!$B$306+0.125,0.25) | E12: =FLOOR(Voorzieningen!$B$306+0.125,0.25) | F12: =FLOOR(Voorzieningen!$B$306+0.125,0.25) | G12: =FLOOR(Voorzieningen!$B$306+0.125,0.25) | H12: =FLOOR(Voorzieningen!$B$306+0.125,0.25) | I12: =FLOOR(Voorzieningen!$B$306+0.125,0.25) | J12: =FLOOR(Voorzieningen!$B$306+0.125,0.25) | ... N12: =FLOOR(Voorzieningen!$B$306+0.125,0.25) | O12: =SUM(C12:N12)
